<robot>




  <link name="hand_palm_link">
    <visual>
      <geometry>
        <mesh filename="./../meshes/allegro/meshes/allegro/base_link_left.obj"/>
      </geometry>
      <!-- LEFT -->
      <origin rpy="-1.57 0 0" xyz="0 0 0 "/>
      <!-- RIGHT -->
      <!-- <origin rpy="0 0 0" xyz="0 0 0 "/> -->
      <material name="black">
        <color rgba="0.2 0.2 0.2 1"/>
      </material>
    </visual>
    <collision>
      <origin rpy="0 0 0" xyz="-0.009300 0 -0.0475"/>
      <geometry>
        <!-- <box size="0.0408 0.1130 0.095"/> -->
        <box size="0.01 0.01 0.01"/>
      </geometry>
    </collision>
    <inertial>
      <origin rpy="0 0 0" xyz="0 0 0.0475"/>
      <mass value="0.4154"/>
      <inertia ixx="1e-4" ixy="0.0" ixz="0.0" iyy="1e-4" iyz="0.0" izz="1e-4"/>
    </inertial>
  </link>

  <link name="palm_aux_link">
    <visual>
      <geometry>
        <box size="0.00125 0.055 0.075"/>
      </geometry>
      <material name="blue">
        <color rgba="0 0 1 1"/>
      </material>
    </visual>
    <collision>
      <geometry>
        <box size="0.00125 0.055 0.075"/>
      </geometry>
    </collision>
  </link>
  <joint name="palm_aux_joint" type="fixed" dont_collapse="true">
    <parent link="hand_palm_link"/>
    <child link="palm_aux_link"/>
    <origin rpy="0 0 0" xyz="0.0125 0.02 -0.04"/>
  </joint>

  <link name="palm_aux2_link">
    <visual>
      <geometry>
        <box size="0.00125 0.075 0.035"/>
      </geometry>
      <material name="blue">
        <color rgba="0 0 1 1"/>
      </material>
    </visual>
    <collision>
      <geometry>
        <box size="0.00125 0.017 0.065"/>
      </geometry>
    </collision>
  </link>
  <joint name="palm_aux_joint2" type="fixed" dont_collapse="true">
    <parent link="hand_palm_link"/>
    <child link="palm_aux2_link"/>
    <origin rpy="0 0 0" xyz="0.0125 -0.02 -0.02"/>
  </joint>


  <!-- ============================================================================= -->
  <!-- FINGERS -->
  <!-- RIGHT HAND due to which finger is number 0 -->
  <!-- for LEFT HAND switch the sign of the **offset_origin_y** and **finger_angle_r** parameters-->
  <link name="hand_link_0.0_link">
    <visual>
      <geometry>
        <mesh filename="./../meshes/allegro/meshes/allegro/link_0.0.obj"/>
      </geometry>
      <material name="black"/>
    </visual>
    <collision>
      <geometry>
        <box size="0.0196 0.0275 0.0164"/>
      </geometry>
      <origin rpy="0 0 0" xyz="0 0 0.0082"/>
    </collision>
    <inertial>
      <mass value="0.0119"/>
      <origin rpy="0 0 0" xyz="0 0 0"/>
      <inertia ixx="1.01666658333e-06" ixy="0.0" ixz="0.0" iyy="6.47677333333e-07" iyz="0.0" izz="1.01666658333e-06"/>
    </inertial>
  </link>
  <joint name="joint_0.0" type="revolute">
    <axis xyz="0 0 1"/>
    <limit effort="0.35" lower="-0.47" upper="0.47" velocity="6.283"/>
    <parent link="hand_palm_link"/>
    <child link="hand_link_0.0_link"/>
    <origin rpy="0.08726646255 0 0" xyz="0 -0.0435 -0.001542"/>
  </joint>
  <link name="hand_link_1.0_link">
    <visual>
      <geometry>
        <mesh filename="./../meshes/allegro/meshes/allegro/link_1.0.obj"/>
      </geometry>
      <material name="black"/>
    </visual>
    <collision>
      <geometry>
        <box size="0.0196 0.0275 0.054"/>
      </geometry>
      <origin rpy="0 0 0" xyz="0 0 0.027"/>
    </collision>
    <inertial>
      <mass value="0.065"/>
      <origin rpy="0 0 0" xyz="0 0 0"/>
      <inertia ixx="7.95654166667e-05" ixy="1.7199e-05" ixz="8.75875e-06" iyy="2.47088833333e-05" iyz="2.413125e-05" izz="7.95654166667e-05"/>
    </inertial>
  </link>
  <joint name="joint_1.0" type="revolute">
    <limit effort="0.35" lower="-0.196" upper="1.61" velocity="6.283"/>
    <axis xyz="0 1 0"/>
    <parent link="hand_link_0.0_link"/>
    <child link="hand_link_1.0_link"/>
    <origin xyz="0 0 0.0164"/>
  </joint>

  <link name="finger_1_contact_1_link">
    <visual>
      <geometry>
        <box size="0.00125 0.017 0.065"/>
      </geometry>
      <material name="blue">
        <color rgba="0 0 1 1"/>
      </material>
    </visual>
    <collision>
      <geometry>
        <box size="0.00125 0.017 0.065"/>
      </geometry>
    </collision>
  </link>

  <joint name="finger_1_contact2_1" type="fixed" dont_collapse="true">
    <parent link="hand_link_1.0_link"/>
    <child link="finger_1_contact_1_link"/>
    <origin rpy="0 0 0" xyz="0.01 0 0.0275"/>
  </joint>

  <link name="hand_link_2.0_link">
    <visual>
      <geometry>
        <mesh filename="./../meshes/allegro/meshes/allegro/link_2.0.obj"/>
      </geometry>
      <material name="black"/>
    </visual>
    <collision>
      <geometry>
        <box size="0.0196 0.0275 0.0384"/>
      </geometry>
      <origin rpy="0 0 0" xyz="0 0 0.0192"/>
    </collision>
    <inertial>
      <mass value="0.0355"/>
      <origin rpy="0 0 0" xyz="0 0 0"/>
      <inertia ixx="2.63979183333e-05" ixy="6.67968e-06" ixz="4.783625e-06" iyy="1.34948516667e-05" iyz="9.372e-06" izz="2.63979183333e-05"/>
    </inertial>
  </link>
  <joint name="joint_2.0" type="revolute">
    <axis xyz="0 1 0"/>
    <limit effort="0.35" lower="-0.174" upper="1.4" velocity="6.283"/> <!-- PREV: 1.709 -->
    <parent link="hand_link_1.0_link"/>
    <child link="hand_link_2.0_link"/>
    <origin xyz="0 0 0.054"/>
  </joint>

  <link name="finger_1_contact_2_link">
    <visual>
      <geometry>
        <box size="0.00125 0.017 0.0375"/>
      </geometry>
      <material name="blue">
        <color rgba="0 0 1 1"/>
      </material>
    </visual>
    <collision>
      <geometry>
        <box size="0.00125 0.017 0.0375"/>
      </geometry>
    </collision>
  </link>

  <joint name="finger_1_contact2_2" type="fixed" dont_collapse="true">
    <parent link="hand_link_2.0_link"/>
    <child link="finger_1_contact_2_link"/>
    <origin rpy="0 0 0" xyz="0.01 0 0.0325"/>
  </joint>

  <link name="hand_link_3.0_link">
    <visual>
      <geometry>
        <mesh filename="./../meshes/allegro/meshes/allegro/link_3.0.obj"/>
      </geometry>
      <material name="black"/>
    </visual>
    <collision>
      <geometry>
        <sphere radius="0.0001"/>
      </geometry>
      <origin rpy="0 0 0" xyz="0 0 0.01335"/>
    </collision>
    <inertial>
      <mass value="0.0096"/>
      <origin rpy="0 0 0" xyz="0 0 0"/>
      <inertia ixx="4.701248e-06" ixy="1.255968e-06" ixz="1.2936e-06" iyy="3.649312e-06" iyz="1.7622e-06" izz="4.701248e-06"/>
    </inertial>
  </link>
  <joint name="joint_3.0" type="revolute">
    <axis xyz="0 1 0"/>
    <limit effort="0.35" lower="-0.227" upper="1.0" velocity="6.283"/> <!-- PREV: 1.618 -->
    <parent link="hand_link_2.0_link"/>
    <child link="hand_link_3.0_link"/>
    <origin xyz="0 0 0.0384"/>
  </joint>

  <!-- <link name="finger_1_contact_3">
    <visual>
      <geometry>
        <box size="0.00125 0.022 0.0375"/>
      </geometry>
      <material name="blue">
        <color rgba="0 0 1 1"/>
      </material>
    </visual>
    <collision>
      <geometry>
        <box size="0.00125 0.022 0.0375"/>
      </geometry>
    </collision>
  </link>

  <joint name="finger_1_contact2_3" type="fixed" dont_collapse="true">
    <parent link="hand_link_3.0_link"/>
    <child link="finger_1_contact_3"/>
    <origin rpy="0 0 0" xyz="0.01 0 -0.005"/>
  </joint> -->

  <link name="hand_link_3.0_link_tip_link">
    <visual>
      <geometry>
        <mesh filename="./../meshes/allegro/meshes/allegro/digit.obj"/>
      </geometry>
      <origin rpy="0 0 0" xyz="-0.02 0.000 -0.015"/>
      <material name="white">
        <color rgba=".9 .9 .9 1"/>
      </material>
    </visual>
    <collision>
      <geometry>
        <sphere radius="0.01235"/>
      </geometry>
      <origin rpy="0 0 0" xyz="0.000 0.000 0"/>
    </collision>
    <inertial>
      <mass value="0.0168"/>
      <origin rpy="0 0 0" xyz="0 0 0"/>
      <inertia ixx="9.68e-07" ixy="0" ixz="0" iyy="9.68e-07" iyz="0" izz="9.68e-07"/>
    </inertial>
  </link>
  <joint name="joint_3.0_tip_link" type="fixed" dont_collapse="true">
    <parent link="hand_link_3.0_link"/>
    <child link="hand_link_3.0_link_tip_link"/>
    <origin rpy="0 0 0" xyz="0.02 0 0.03"/>
  </joint>

  <link name="finger_1_contact_3_tip_link">
    <visual>
      <geometry>
        <box size="0.00075 0.02 0.02"/>
      </geometry>
      <material name="blue">
        <color rgba="0 0 1 1"/>
      </material>
    </visual>
    <collision>
      <geometry>
        <box size="0.00075 0.02 0.02"/>
      </geometry>
    </collision>
  </link>

  <joint name="finger_1_contact2_3_tip" type="fixed" dont_collapse="true">
    <parent link="hand_link_3.0_link_tip_link"/>
    <child link="finger_1_contact_3_tip_link"/>
    <origin rpy="0 0 0" xyz="0 0 0"/>
  </joint>

  <link name="hand_link_4.0_link">
    <visual>
      <geometry>
        <mesh filename="./../meshes/allegro/meshes/allegro/link_0.0.obj"/>
      </geometry>
      <material name="black"/>
    </visual>
    <collision>
      <geometry>
        <box size="0.0196 0.0275 0.0164"/>
      </geometry>
      <origin rpy="0 0 0" xyz="0 0 0.0082"/>
    </collision>
    <inertial>
      <mass value="0.0119"/>
      <origin rpy="0 0 0" xyz="0 0 0"/>
      <inertia ixx="1.01666658333e-06" ixy="0.0" ixz="0.0" iyy="6.47677333333e-07" iyz="0.0" izz="1.01666658333e-06"/>
    </inertial>
  </link>
  <joint name="joint_4.0" type="revolute">
    <axis xyz="0 0 1"/>
    <limit effort="0.35" lower="-0.47" upper="0.47" velocity="6.283"/>
    <parent link="hand_palm_link"/>
    <child link="hand_link_4.0_link"/>
    <origin rpy="0.0 0 0" xyz="0 0 0.0007"/>
  </joint>
  <link name="hand_link_5.0_link">
    <visual>
      <geometry>
        <mesh filename="./../meshes/allegro/meshes/allegro/link_1.0.obj"/>
      </geometry>
      <material name="black"/>
    </visual>
    <collision>
      <geometry>
        <box size="0.0196 0.0275 0.054"/>
      </geometry>
      <origin rpy="0 0 0" xyz="0 0 0.027"/>
    </collision>
    <inertial>
      <mass value="0.065"/>
      <origin rpy="0 0 0" xyz="0 0 0"/>
      <inertia ixx="7.95654166667e-05" ixy="1.7199e-05" ixz="8.75875e-06" iyy="2.47088833333e-05" iyz="2.413125e-05" izz="7.95654166667e-05"/>
    </inertial>
  </link>
  <joint name="joint_5.0" type="revolute">
    <limit effort="0.35" lower="-0.196" upper="1.61" velocity="6.283"/>
    <axis xyz="0 1 0"/>
    <parent link="hand_link_4.0_link"/>
    <child link="hand_link_5.0_link"/>
    <origin xyz="0 0 0.0164"/>
  </joint>

  <link name="finger_2_contact_5_link">
    <visual>
      <geometry>
        <box size="0.00125 0.017 0.065"/>
      </geometry>
      <material name="blue">
        <color rgba="0 0 1 1"/>
      </material>
    </visual>
    <collision>
      <geometry>
        <box size="0.00125 0.017 0.065"/>
      </geometry>
    </collision>
  </link>

  <joint name="finger_2_contact5_1" type="fixed" dont_collapse="true">
    <parent link="hand_link_5.0_link"/>
    <child link="finger_2_contact_5_link"/>
    <origin rpy="0 0 0" xyz="0.01 0 0.0275"/>
  </joint>

  <link name="hand_link_6.0_link">
    <visual>
      <geometry>
        <mesh filename="./../meshes/allegro/meshes/allegro/link_2.0.obj"/>
      </geometry>
      <material name="black"/>
    </visual>
    <collision>
      <geometry>
        <box size="0.0196 0.0275 0.0384"/>
      </geometry>
      <origin rpy="0 0 0" xyz="0 0 0.0192"/>
    </collision>
    <inertial>
      <mass value="0.0355"/>
      <origin rpy="0 0 0" xyz="0 0 0"/>
      <inertia ixx="2.63979183333e-05" ixy="6.67968e-06" ixz="4.783625e-06" iyy="1.34948516667e-05" iyz="9.372e-06" izz="2.63979183333e-05"/>
    </inertial>
  </link>
  <joint name="joint_6.0" type="revolute">
    <axis xyz="0 1 0"/>
    <limit effort="0.35" lower="-0.174" upper="1.4" velocity="6.283"/>  <!-- PREV: 1.709 -->
    <parent link="hand_link_5.0_link"/>
    <child link="hand_link_6.0_link"/>
    <origin xyz="0 0 0.054"/>
  </joint>

  <link name="finger_2_contact_6_link">
    <visual>
      <geometry>
        <box size="0.00125 0.017 0.0375"/>
      </geometry>
      <material name="blue">
        <color rgba="0 0 1 1"/>
      </material>
    </visual>
    <collision>
      <geometry>
        <box size="0.00125 0.017 0.0375"/>
      </geometry>
    </collision>
  </link>

  <joint name="finger_2_contact6_2" type="fixed" dont_collapse="true">
    <parent link="hand_link_6.0_link"/>
    <child link="finger_2_contact_6_link"/>
    <origin rpy="0 0 0" xyz="0.01 0 0.0325"/>
  </joint>

  <link name="hand_link_7.0_link">
    <visual>
      <geometry>
        <mesh filename="./../meshes/allegro/meshes/allegro/link_3.0.obj"/>
      </geometry>
      <material name="black"/>
    </visual>
    <collision>
      <geometry>
        <sphere radius="0.0001"/>
      </geometry>
    </collision>
    <inertial>
      <mass value="0.0096"/>
      <origin rpy="0 0 0" xyz="0 0 0"/>
      <inertia ixx="4.701248e-06" ixy="1.255968e-06" ixz="1.2936e-06" iyy="3.649312e-06" iyz="1.7622e-06" izz="4.701248e-06"/>
    </inertial>
  </link>
  <joint name="joint_7.0" type="revolute">
    <axis xyz="0 1 0"/>
    <limit effort="0.35" lower="-0.227" upper="1." velocity="6.283"/>  <!-- PREV: 1.618 -->
    <parent link="hand_link_6.0_link"/>
    <child link="hand_link_7.0_link"/>
    <origin xyz="0 0 0.0384"/>
  </joint>

  <!-- <link name="finger_2_contact_7">
    <visual>
      <geometry>
        <box size="0.00125 0.022 0.0375"/>
      </geometry>
      <material name="blue">
        <color rgba="0 0 1 1"/>
      </material>
    </visual>
    <collision>
      <geometry>
        <box size="0.00125 0.022 0.0375"/>
      </geometry>
    </collision>
  </link>

  <joint name="finger_2_contact2_7" type="fixed" dont_collapse="true">
    <parent link="hand_link_7.0_link"/>
    <child link="finger_2_contact_7"/>
    <origin rpy="0 0 0" xyz="0.01 0 -0.005"/>
  </joint> -->

  <link name="hand_link_7.0_link_tip_link">
    <visual>
      <geometry>
        <mesh filename="./../meshes/allegro/meshes/allegro/digit.obj"/>
      </geometry>
      <origin rpy="0 0 0" xyz="-0.02 0.000 -0.015"/>
      <material name="white">
        <color rgba=".9 .9 .9 1"/>
      </material>
    </visual>
    <collision>
      <geometry>
        <sphere radius="0.01235"/>
      </geometry>
    </collision>
    <inertial>
      <mass value="0.0168"/>
      <origin rpy="0 0 0" xyz="0 0 0"/>
      <inertia ixx="9.68e-07" ixy="0" ixz="0" iyy="9.68e-07" iyz="0" izz="9.68e-07"/>
    </inertial>
  </link>
  <joint name="joint_7.0_tip_link" type="fixed" dont_collapse="true">
    <parent link="hand_link_7.0_link"/>
    <child link="hand_link_7.0_link_tip_link"/>
    <origin rpy="0 0 0" xyz="0.02 0 0.03"/>
  </joint>

  <link name="finger_2_contact_7_tip_link">
    <visual>
      <geometry>
        <box size="0.00075 0.02 0.02"/>
      </geometry>
      <material name="blue">
        <color rgba="0 0 1 1"/>
      </material>
    </visual>
    <collision>
      <geometry>
        <box size="0.00075 0.02 0.02"/>
      </geometry>
    </collision>
  </link>

  <joint name="finger_2_contact2_7_tip" type="fixed" dont_collapse="true">
    <parent link="hand_link_7.0_link_tip_link"/>
    <child link="finger_2_contact_7_tip_link"/>
    <origin rpy="0 0 0" xyz="0 0 0"/>
  </joint>

  <link name="hand_link_8.0_link">
    <visual>
      <geometry>
        <mesh filename="./../meshes/allegro/meshes/allegro/link_0.0.obj"/>
      </geometry>
      <material name="black"/>
    </visual>
    <collision>
      <geometry>
        <box size="0.0196 0.0275 0.0164"/>
      </geometry>
      <origin rpy="0 0 0" xyz="0 0 0.0082"/>
    </collision>
    <inertial>
      <mass value="0.0119"/>
      <origin rpy="0 0 0" xyz="0 0 0"/>
      <inertia ixx="1.01666658333e-06" ixy="0.0" ixz="0.0" iyy="6.47677333333e-07" iyz="0.0" izz="1.01666658333e-06"/>
    </inertial>
  </link>
  <joint name="joint_8.0" type="revolute">
    <axis xyz="0 0 1"/>
    <limit effort="0.35" lower="-0.47" upper="0.47" velocity="6.283"/>
    <parent link="hand_palm_link"/>
    <child link="hand_link_8.0_link"/>
    <origin rpy="-0.08726646255 0 0" xyz="0 0.0435 -0.001542"/>
  </joint>
  <link name="hand_link_9.0_link">
    <visual>
      <geometry>
        <mesh filename="./../meshes/allegro/meshes/allegro/link_1.0.obj"/>
      </geometry>
      <material name="black"/>
    </visual>
    <collision>
      <geometry>
        <box size="0.0196 0.0275 0.054"/>
      </geometry>
      <origin rpy="0 0 0" xyz="0 0 0.027"/>
    </collision>
    <inertial>
      <mass value="0.065"/>
      <origin rpy="0 0 0" xyz="0 0 0"/>
      <inertia ixx="7.95654166667e-05" ixy="1.7199e-05" ixz="8.75875e-06" iyy="2.47088833333e-05" iyz="2.413125e-05" izz="7.95654166667e-05"/>
    </inertial>
  </link>
  <joint name="joint_9.0" type="revolute">
    <limit effort="0.35" lower="-0.196" upper="1.61" velocity="6.283"/>
    <axis xyz="0 1 0"/>
    <parent link="hand_link_8.0_link"/>
    <child link="hand_link_9.0_link"/>
    <origin xyz="0 0 0.0164"/>
  </joint>

  <link name="finger_3_contact_9_link">
    <visual>
      <geometry>
        <box size="0.00125 0.017 0.065"/>
      </geometry>
      <material name="blue">
        <color rgba="0 0 1 1"/>
      </material>
    </visual>
    <collision>
      <geometry>
        <box size="0.00125 0.017 0.065"/>
      </geometry>
    </collision>
  </link>

  <joint name="finger_3_contact9_1" type="fixed" dont_collapse="true">
    <parent link="hand_link_9.0_link"/>
    <child link="finger_3_contact_9_link"/>
    <origin rpy="0 0 0" xyz="0.01 0 0.0275"/>
  </joint>

  <link name="hand_link_10._link">
    <visual>
      <geometry>
        <mesh filename="./../meshes/allegro/meshes/allegro/link_2.0.obj"/>
      </geometry>
      <material name="black"/>
    </visual>
    <collision>
      <geometry>
        <box size="0.0196 0.0275 0.0384"/>
      </geometry>
      <origin rpy="0 0 0" xyz="0 0 0.0192"/>
    </collision>
    <inertial>
      <mass value="0.0355"/>
      <origin rpy="0 0 0" xyz="0 0 0"/>
      <inertia ixx="2.63979183333e-05" ixy="6.67968e-06" ixz="4.783625e-06" iyy="1.34948516667e-05" iyz="9.372e-06" izz="2.63979183333e-05"/>
    </inertial>
  </link>
  <joint name="joint_10.0" type="revolute">
    <axis xyz="0 1 0"/>
    <limit effort="0.35" lower="-0.174" upper="1.4" velocity="6.283"/>  <!-- PREV: 1.709 -->
    <parent link="hand_link_9.0_link"/>
    <child link="hand_link_10._link"/>
    <origin xyz="0 0 0.054"/>
  </joint>

  <link name="finger_3_contact_10_link">
    <visual>
      <geometry>
        <box size="0.00125 0.017 0.0375"/>
      </geometry>
      <material name="blue">
        <color rgba="0 0 1 1"/>
      </material>
    </visual>
    <collision>
      <geometry>
        <box size="0.00125 0.017 0.0375"/>
      </geometry>
    </collision>
  </link>

  <joint name="finger_3_contact10_2" type="fixed" dont_collapse="true">
    <parent link="hand_link_10._link"/>
    <child link="finger_3_contact_10_link"/>
    <origin rpy="0 0 0" xyz="0.01 0 0.0325"/>
  </joint>

  <link name="hand_link_11._link">
    <visual>
      <geometry>
        <mesh filename="./../meshes/allegro/meshes/allegro/link_3.0.obj"/>
      </geometry>
      <material name="black"/>
    </visual>
    <collision>
      <geometry>
        <sphere radius="0.0001"/>
      </geometry>
    </collision>
    <inertial>
      <mass value="0.0096"/>
      <origin rpy="0 0 0" xyz="0 0 0"/>
      <inertia ixx="4.701248e-06" ixy="1.255968e-06" ixz="1.2936e-06" iyy="3.649312e-06" iyz="1.7622e-06" izz="4.701248e-06"/>
    </inertial>
  </link>
  <joint name="joint_11.0" type="revolute">
    <axis xyz="0 1 0"/>
    <limit effort="0.35" lower="-0.227" upper="1" velocity="6.283"/>  <!-- PREV: 1.618 -->
    <parent link="hand_link_10._link"/>
    <child link="hand_link_11._link"/>
    <origin xyz="0 0 0.0384"/>
  </joint>

  <!-- <link name="finger_3_contact_11">
    <visual>
      <geometry>
        <box size="0.00125 0.022 0.0375"/>
      </geometry>
      <material name="blue">
        <color rgba="0 0 1 1"/>
      </material>
    </visual>
    <collision>
      <geometry>
        <box size="0.00125 0.022 0.0375"/>
      </geometry>
    </collision>
  </link>

  <joint name="finger_3_contact2_11" type="fixed" dont_collapse="true">
    <parent link="hand_link_11._link"/>
    <child link="finger_3_contact_11"/>
    <origin rpy="0 0 0" xyz="0.01 0 -0.005"/>
  </joint> -->

  <link name="hand_link_11._link_tip_link">
    <visual>
      <geometry>
        <mesh filename="./../meshes/allegro/meshes/allegro/digit.obj"/>
      </geometry>
      <origin rpy="0 0 0" xyz="-0.02 0.000 -0.015"/>
      <material name="white">
        <color rgba=".9 .9 .9 1"/>
      </material>
    </visual>
    <collision>
      <geometry>
        <sphere radius="0.01235"/>
      </geometry>
    </collision>
    <inertial>
      <mass value="0.0168"/>
      <origin rpy="0 0 0" xyz="0 0 0"/>
      <inertia ixx="9.68e-07" ixy="0" ixz="0" iyy="9.68e-07" iyz="0" izz="9.68e-07"/>
    </inertial>
  </link>
  <joint name="joint_11.0_tip_link" type="fixed" dont_collapse="true">
    <parent link="hand_link_11._link"/>
    <child link="hand_link_11._link_tip_link"/>
    <origin rpy="0 0 0" xyz="0.02 0 0.03"/>
  </joint>

  <link name="finger_3_contact_11_tip_link">
    <visual>
      <geometry>
        <box size="0.00075 0.02 0.02"/>
      </geometry>
      <material name="blue">
        <color rgba="0 0 1 1"/>
      </material>
    </visual>
    <collision>
      <geometry>
        <box size="0.00075 0.02 0.02"/>
      </geometry>
    </collision>
  </link>

  <joint name="finger_3_contact2_11_tip" type="fixed" dont_collapse="true">
    <parent link="hand_link_11._link_tip_link"/>
    <child link="finger_3_contact_11_tip_link"/>
    <origin rpy="0 0 0" xyz="0 0 0"/>
  </joint>

  <!-- THUMB -->
  <link name="hand_link_12._link">
    <visual>
      <geometry>
        <!-- RIGHT -->
        <!-- <mesh filename="./../meshes/allegro/meshes/allegro/link_12.0_right.obj"/> -->
        <!-- LEFT -->
        <mesh filename="./../meshes/allegro/meshes/allegro/link_12.0_left.obj" />
      </geometry>
      <material name="black">
        <color rgba=".2 .2 .2 1"/>
      </material>
    </visual>
    <collision>
      <geometry>
        <box size="0.0358 0.034 0.0455"/>
      </geometry>
      <!-- RIGHT -->
      <!-- <origin rpy="0 0 0" xyz="-0.0179 0.009 0.0145"/> -->
      <!-- LEFT -->
      <origin rpy="0 0 0" xyz="-0.0179 -0.09 0.145"/>
    </collision>
    <inertial>
      <mass value="0.0176"/>
      <origin rpy="0 0 0" xyz="0 0 0"/>
      <inertia ixx="1.89273333333e-5" ixy="7.16716e-06" ixz="5.35568e-06" iyy="1.43008213333e-05" iyz="6.8068e-06" izz="1.89273333333e-05"/>
    </inertial>
  </link>
  <joint name="joint_12.0" type="revolute">
    <axis xyz="1 0 0"/>
    <limit effort="0.35" lower="0.263" upper="0.7" velocity="6.283"/>  <!-- PREV: 1.396 -->
    <parent link="hand_palm_link"/>
    <child link="hand_link_12._link"/>
    <origin rpy="0 -1.65806278845 1.5707963259" xyz="-0.0182 -0.019333 -0.045987"/>
  </joint>
  <link name="hand_link_13._link">
    <visual>
      <geometry>
        <mesh filename="./../meshes/allegro/meshes/allegro/link_13.0.obj"/>
      </geometry>
      <material name="black">
        <color rgba=".2 .2 .2 1"/>
      </material>
    </visual>
    <collision>
      <geometry>
        <box size="0.0196 0.0275 0.0177"/>
      </geometry>
      <origin rpy="0 0 0" xyz="0 0 0.00885"/>
    </collision>
    <inertial>
      <mass value="0.0119"/>
      <origin rpy="0 0 0" xyz="0 0 0"/>
      <inertia ixx="4.24250866667e-06" ixy="1.032087e-06" ixz="1.603525e-06" iyy="4.52362633333e-06" iyz="1.44808125e-06" izz="4.24250866667e-06"/>
    </inertial>
  </link>
  <joint name="joint_13.0" type="revolute">
    <axis xyz="0 0 -1"/>
    <limit effort="0.35" lower="-1.05" upper="0.7" velocity="6.283"/>  <!-- -0.105 EL LOWER original, PREV 1.163 -->
    <parent link="hand_link_12._link"/>
    <child link="hand_link_13._link"/>
    <!-- LEFT -->
    <origin xyz="-0.027 -0.005 0" rpy="0 0 -1.57"/> <!-- -0.027 -0.005 -0.0399 -->
    <!-- RIGHT -->
    <!-- <origin xyz="-0.027 0.005 0.0399"/> -->
  </joint>
  <link name="hand_link_14._link">
    <visual>
      <geometry>
        <mesh filename="./../meshes/allegro/meshes/allegro/link_14.0.obj"/>
      </geometry>
      <material name="black">
      </material>
    </visual>
    <collision>
      <geometry>
        <box size="0.0196 0.0275 0.0514"/>
      </geometry>
      <origin rpy="0 0 0" xyz="0 0 0.0257"/>
    </collision>
    <inertial>
      <mass value="0.038"/>
      <origin rpy="0 0 0" xyz="0 0 0"/>
      <inertia ixx="4.30439933333e-05" ixy="9.57068e-06" ixz="5.1205e-06" iyy="1.44451933333e-05" iyz="1.342825e-05" izz="4.30439933333e-05"/>
    </inertial>
  </link>
  <joint name="joint_14.0" type="revolute">
    <axis xyz="0 1 0"/>
    <limit effort="0.35" lower="-0.189" upper="0.8" velocity="6.283"/>  <!-- PREV: 1.644 -->
    <parent link="hand_link_13._link"/>
    <child link="hand_link_14._link"/>
    <origin xyz="0 0 0.0177"/>
  </joint>

<link name="finger_4_contact_14_link">
    <visual>
      <geometry>
        <box size="0.00125 0.022 0.0375"/>
      </geometry>
      <material name="blue">
        <color rgba="0 0 1 1"/>
      </material>
    </visual>
    <collision>
      <geometry>
        <box size="0.00125 0.022 0.0375"/>
      </geometry>
    </collision>
  </link>

  <joint name="finger_4_contact2_14" type="fixed" dont_collapse="true">
    <parent link="hand_link_14._link"/>
    <child link="finger_4_contact_14_link"/>
    <origin rpy="0 0 0" xyz="0.01 0 0.005"/>
  </joint>

  <link name="hand_link_15._link">
    <visual>
      <geometry>
        <mesh filename="./../meshes/allegro/meshes/allegro/link_15.0.obj"/>
      </geometry>
      <material name="black">
    	</material>
    </visual>
    <collision>
      <geometry>
        <sphere radius="0.0001"/>
      </geometry>
      <origin rpy="0 0 0" xyz="0 0 0.02115"/>
    </collision>
    <inertial>
      <mass value="0.0388"/>
      <origin rpy="0 0 0" xyz="0 0 0"/>
      <inertia ixx="3.29223173333e-05" ixy="8.042076e-06" ixz="5.2283e-06" iyy="1.47493026667e-5" iyz="1.1283525e-5" izz="3.29223173333e-05"/>
    </inertial>
  </link>
  <joint name="joint_15.0" type="revolute">
    <axis xyz="0 1 0"/>
    <limit effort="0.35" lower="-0.162" upper="1.719" velocity="6.283"/>
    <parent link="hand_link_14._link"/>
    <child link="hand_link_15._link"/>
    <origin xyz="0 0 0.0514"/>
  </joint>

  <link name="finger_4_contact_15_link">
    <visual>
      <geometry>
        <box size="0.00125 0.022 0.035"/>
      </geometry>
      <material name="blue">
        <color rgba="0 0 1 1"/>
      </material>
    </visual>
    <collision>
      <geometry>
        <box size="0.00125 0.022 0.035"/>
      </geometry>
    </collision>
  </link>

  <joint name="finger_4_contact2_15" type="fixed" dont_collapse="true">
    <parent link="hand_link_15._link"/>
    <child link="finger_4_contact_15_link"/>
    <origin rpy="0 0 0" xyz="0.01 0 0.005"/>
  </joint>

  <link name="hand_link_15._link_tip_link">
    <visual>
      <geometry>
        <mesh filename="./../meshes/allegro/meshes/allegro/digit.obj"/>
      </geometry>
      <origin rpy="0 0 0" xyz="-0.02 0.000 -0.015"/>
      <material name="white">
        <color rgba=".9 .9 .9 1"/>
      </material>
    </visual>
    <collision>
      <geometry>
        <sphere radius="0.01235"/>
      </geometry>
    </collision>
    <inertial>
      <mass value="0.0168"/>
      <origin rpy="0 0 0" xyz="0 0 0"/>
      <inertia ixx="9.68e-07" ixy="0" ixz="0" iyy="9.68e-07" iyz="0" izz="9.68e-07"/>
    </inertial>
  </link>
  <joint name="joint_15.0_tip_link" type="fixed" dont_collapse="true">
    <parent link="hand_link_15._link"/>
    <child link="hand_link_15._link_tip_link"/>
    <origin rpy="0 0 0" xyz="0.02 0 0.0455"/>
  </joint>

  <link name="finger_4_contact_15_tip_link">
    <visual>
      <geometry>
        <box size="0.00075 0.02 0.02"/>
      </geometry>
      <material name="blue">
        <color rgba="0 0 1 1"/>
      </material>
    </visual>
    <collision>
      <geometry>
        <box size="0.00075 0.02 0.02"/>
      </geometry>
    </collision>
  </link>

  <joint name="finger_4_contact2_15_tip" type="fixed" dont_collapse="true">
    <parent link="hand_link_15._link_tip_link"/>
    <child link="finger_4_contact_15_tip_link"/>
    <origin rpy="0 0 0" xyz="0.0 0 0.0"/>
  </joint>

</robot>