<?xml version="1.0" ?>
<!-- =================================================================================== -->
<!-- |    This document was autogenerated by xacro from gen3.xacro                     | -->
<!-- |    EDITING THIS FILE BY HAND IS NOT RECOMMENDED                                 | -->
<!-- =================================================================================== -->
<robot name="gen3">
  <link name="world"/>
  
  <joint name="base_joint" type="fixed" dont_collapse="true">
    <origin rpy="0 0 0" xyz="0 0 0"/>
    <parent link="world"/>
    <child link="base_link"/>
  </joint>
  <link name="base_link">
    <inertial>
      <origin rpy="0 0 0" xyz="-0.000648 -0.000166 0.084487"/>
      <mass value="1.697"/>
      <inertia ixx="0.004622" ixy="9E-06" ixz="6E-05" iyy="0.004495" iyz="9E-06" izz="0.002079"/>
    </inertial>
    <visual>
      <origin rpy="0 0 0" xyz="0 0 0"/>
      <geometry>
        <mesh filename="./../meshes/gen3/7dof/base_link.dae"/>
      </geometry>
      <material name="">
        <color rgba="0.75294 0.75294 0.75294 1"/>
      </material>
    </visual>
    <collision>
      <origin rpy="0 0 0" xyz="0 0 0"/>
      <geometry>
        <mesh filename="./../meshes/gen3/7dof/base_link.dae"/>
      </geometry>
    </collision>
  </link>
  <link name="shoulder_link">
    <inertial>
      <origin rpy="0 0 0" xyz="-2.3E-05 -0.010364 -0.07336"/>
      <mass value="1.3773"/>
      <inertia ixx="0.00457" ixy="1E-06" ixz="2E-06" iyy="0.004831" iyz="0.000448" izz="0.001409"/>
    </inertial>
    <visual>
      <origin rpy="0 0 0" xyz="0 0 0"/>
      <geometry>
        <mesh filename="./../meshes/gen3/7dof/shoulder_link.dae"/>
      </geometry>
      <material name="">
        <color rgba="0.75294 0.75294 0.75294 1"/>
      </material>
    </visual>
    <collision>
      <origin rpy="0 0 0" xyz="0 0 0"/>
      <geometry>
        <mesh filename="./../meshes/gen3/7dof/shoulder_link.dae"/>
      </geometry>
    </collision>
  </link>
  <joint name="arm_joint_1" type="continuous">
    <origin rpy="3.1416 2.7629E-18 -4.9305E-36" xyz="0 0 0.15643"/>
    <parent link="base_link"/>
    <child link="shoulder_link"/>
    <axis xyz="0 0 1"/>
    <limit effort="39" velocity="1.3963"/>
  </joint>
  <link name="half_arm_1_link">
    <inertial>
      <origin rpy="0 0 0" xyz="-4.4E-05 -0.09958 -0.013278"/>
      <mass value="1.1636"/>
      <inertia ixx="0.011088" ixy="5E-06" ixz="0" iyy="0.001072" iyz="-0.000691" izz="0.011255"/>
    </inertial>
    <visual>
      <origin rpy="0 0 0" xyz="0 0 0"/>
      <geometry>
        <mesh filename="./../meshes/gen3/7dof/half_arm_1_link.dae"/>
      </geometry>
      <material name="">
        <color rgba="0.75294 0.75294 0.75294 1"/>
      </material>
    </visual>
    <collision>
      <origin rpy="0 0 0" xyz="0 0 0"/>
      <geometry>
        <mesh filename="./../meshes/gen3/7dof/half_arm_1_link.dae"/>
      </geometry>
    </collision>
  </link>
  <joint name="arm_joint_2" type="revolute">
    <origin rpy="1.5708 2.1343E-17 -1.1102E-16" xyz="0 0.005375 -0.12838"/>
    <parent link="shoulder_link"/>
    <child link="half_arm_1_link"/>
    <axis xyz="0 0 1"/>
    <limit effort="39" lower="-2.24" upper="2.24" velocity="1.3963"/>
  </joint>
  <link name="half_arm_2_link">
    <inertial>
      <origin rpy="0 0 0" xyz="-4.4E-05 -0.006641 -0.117892"/>
      <mass value="1.1636"/>
      <inertia ixx="0.010932" ixy="0" ixz="-7E-06" iyy="0.011127" iyz="0.000606" izz="0.001043"/>
    </inertial>
    <visual>
      <origin rpy="0 0 0" xyz="0 0 0"/>
      <geometry>
        <mesh filename="./../meshes/gen3/7dof/half_arm_2_link.dae"/>
      </geometry>
      <material name="">
        <color rgba="0.75294 0.75294 0.75294 1"/>
      </material>
    </visual>
    <collision>
      <origin rpy="0 0 0" xyz="0 0 0"/>
      <geometry>
        <mesh filename="./../meshes/gen3/7dof/half_arm_2_link.dae"/>
      </geometry>
    </collision>
  </link>
  <joint name="arm_joint_3" type="continuous">
    <origin rpy="-1.5708 1.2326E-32 -2.9122E-16" xyz="0 -0.21038 -0.006375"/>
    <parent link="half_arm_1_link"/>
    <child link="half_arm_2_link"/>
    <axis xyz="0 0 1"/>
    <limit effort="39" velocity="1.3963"/>
  </joint>
  <link name="forearm_link">
    <inertial>
      <origin rpy="0 0 0" xyz="-1.8E-05 -0.075478 -0.015006"/>
      <mass value="0.9302"/>
      <inertia ixx="0.008147" ixy="-1E-06" ixz="0" iyy="0.000631" iyz="-0.0005" izz="0.008316"/>
    </inertial>
    <visual>
      <origin rpy="0 0 0" xyz="0 0 0"/>
      <geometry>
        <mesh filename="./../meshes/gen3/7dof/forearm_link.dae"/>
      </geometry>
      <material name="">
        <color rgba="0.75294 0.75294 0.75294 1"/>
      </material>
    </visual>
    <collision>
      <origin rpy="0 0 0" xyz="0 0 0"/>
      <geometry>
        <mesh filename="./../meshes/gen3/7dof/forearm_link.dae"/>
      </geometry>
    </collision>
  </link>
  <joint name="arm_joint_4" type="revolute">
    <origin rpy="1.5708 -6.6954E-17 -1.6653E-16" xyz="0 0.006375 -0.21038"/>
    <parent link="half_arm_2_link"/>
    <child link="forearm_link"/>
    <axis xyz="0 0 1"/>
    <limit effort="39" lower="-2.57" upper="2.57" velocity="1.3963"/>
  </joint>
  <link name="spherical_wrist_1_link">
    <inertial>
      <origin rpy="0 0 0" xyz="1E-06 -0.009432 -0.063883"/>
      <mass value="0.6781"/>
      <inertia ixx="0.001596" ixy="0" ixz="0" iyy="0.001607" iyz="0.000256" izz="0.000399"/>
    </inertial>
    <visual>
      <origin rpy="0 0 0" xyz="0 0 0"/>
      <geometry>
        <mesh filename="./../meshes/gen3/7dof/spherical_wrist_1_link.dae"/>
      </geometry>
      <material name="">
        <color rgba="0.75294 0.75294 0.75294 1"/>
      </material>
    </visual>
    <collision>
      <origin rpy="0 0 0" xyz="0 0 0"/>
      <geometry>
        <mesh filename="./../meshes/gen3/7dof/spherical_wrist_1_link.dae"/>
      </geometry>
    </collision>
  </link>
  <joint name="arm_joint_5" type="continuous">
    <origin rpy="-1.5708 2.2204E-16 -6.373E-17" xyz="0 -0.20843 -0.006375"/>
    <parent link="forearm_link"/>
    <child link="spherical_wrist_1_link"/>
    <axis xyz="0 0 1"/>
    <limit effort="9" velocity="1.2218"/>
  </joint>
  <link name="spherical_wrist_2_link">
    <inertial>
      <origin rpy="0 0 0" xyz="1E-06 -0.045483 -0.00965"/>
      <mass value="0.6781"/>
      <inertia ixx="0.001641" ixy="0" ixz="0" iyy="0.00041" iyz="-0.000278" izz="0.001641"/>
    </inertial>
    <visual>
      <origin rpy="0 0 0" xyz="0 0 0"/>
      <geometry>
        <mesh filename="./../meshes/gen3/7dof/spherical_wrist_2_link.dae"/>
      </geometry>
      <material name="">
        <color rgba="0.75294 0.75294 0.75294 1"/>
      </material>
    </visual>
    <collision>
      <origin rpy="0 0 0" xyz="0 0 0"/>
      <geometry>
        <mesh filename="./../meshes/gen3/7dof/spherical_wrist_2_link.dae"/>
      </geometry>
    </collision>
  </link>
  <joint name="arm_joint_6" type="revolute">
    <origin rpy="1.5708 9.2076E-28 -8.2157E-15" xyz="0 0.00017505 -0.10593"/>
    <parent link="spherical_wrist_1_link"/>
    <child link="spherical_wrist_2_link"/>
    <axis xyz="0 0 1"/>
    <limit effort="9" lower="-2.09" upper="2.09" velocity="1.2218"/>
  </joint>
  <link name="bracelet_link">
    <inertial>
      <origin rpy="0 0 0" xyz="-9.3E-05 0.000132 -0.022905"/>
      <mass value="0.364"/>
      <inertia ixx="0.000214" ixy="0" ixz="1E-06" iyy="0.000223" iyz="-2E-06" izz="0.00024"/>
    </inertial>
    <visual>
      <origin rpy="0 0 0" xyz="0 0 0"/>
      <geometry>
        <mesh filename="./../meshes/gen3/7dof/bracelet_no_vision_link.dae"/>
      </geometry>
      <material name="">
        <color rgba="0.75294 0.75294 0.75294 1"/>
      </material>
    </visual>
    <collision>
      <origin rpy="0 0 0" xyz="0 0 0"/>
      <geometry>
        <mesh filename="./../meshes/gen3/7dof/bracelet_no_vision_link.dae"/>
      </geometry>
    </collision>
  </link>
  <joint name="arm_joint_7" type="continuous">
    <origin rpy="-1.5708 -5.5511E-17 9.6396E-17" xyz="0 -0.10593 -0.00017505"/>
    <parent link="spherical_wrist_2_link"/>
    <child link="bracelet_link"/>
    <axis xyz="0 0 1"/>
    <limit effort="9" velocity="1.2218"/>
  </joint>
  <link name="end_effector_link"/>
  <joint name="end_effector" type="fixed" dont_collapse="true">
    <origin rpy="3.14159265358979 1.09937075168372E-32 0" xyz="0 0 -0.0615250000000001"/>
    <parent link="bracelet_link"/>
    <child link="end_effector_link"/>
    <axis xyz="0 0 0"/>
  </joint>
  <link name="tool_frame"/>
  <joint name="tool_frame_joint" type="fixed" dont_collapse="true">
    <origin rpy="0 0 0" xyz="0 0 0"/>
    <parent link="end_effector_link"/>
    <child link="tool_frame"/>
    <axis xyz="0 0 0"/>
  </joint>



  <link name="hand_palm_link">
    <visual>
      <geometry>
        <mesh filename="./../meshes/allegro/meshes/allegro/base_link_left.obj"/>
      </geometry>
      <!-- LEFT -->
      <origin rpy="-1.57 0 0" xyz="0 0 0 "/>
      <!-- RIGHT -->
      <!-- <origin rpy="0 0 0" xyz="0 0 0 "/> -->
      <material name="black">
        <color rgba="0.2 0.2 0.2 1"/>
      </material>
    </visual>
    <collision>
      <origin rpy="0 0 0" xyz="-0.009300 0 -0.0475"/>
      <geometry>
        <!-- <box size="0.0408 0.1130 0.095"/> -->
        <box size="0.01 0.01 0.01"/>
      </geometry>
    </collision>
    <inertial>
      <origin rpy="0 0 0" xyz="0 0 0.0475"/>
      <mass value="0.4154"/>
      <inertia ixx="1e-4" ixy="0.0" ixz="0.0" iyy="1e-4" iyz="0.0" izz="1e-4"/>
    </inertial>
  </link>

  <link name="palm_aux_link">
    <visual>
      <geometry>
        <box size="0.00125 0.055 0.075"/>
      </geometry>
      <material name="blue">
        <color rgba="0 0 1 1"/>
      </material>
    </visual>
    <collision>
      <geometry>
        <box size="0.00125 0.055 0.075"/>
      </geometry>
    </collision>
  </link>
  <joint name="palm_aux_joint" type="fixed" dont_collapse="true">
    <parent link="hand_palm_link"/>
    <child link="palm_aux_link"/>
    <origin rpy="0 0 0" xyz="0.0125 0.02 -0.04"/>
  </joint>

  <link name="palm_aux2_link">
    <visual>
      <geometry>
        <box size="0.00125 0.075 0.035"/>
      </geometry>
      <material name="blue">
        <color rgba="0 0 1 1"/>
      </material>
    </visual>
    <collision>
      <geometry>
        <box size="0.00125 0.017 0.065"/>
      </geometry>
    </collision>
  </link>
  <joint name="palm_aux_joint2" type="fixed" dont_collapse="true">
    <parent link="hand_palm_link"/>
    <child link="palm_aux2_link"/>
    <origin rpy="0 0 0" xyz="0.0125 -0.02 -0.02"/>
  </joint>


  <!-- ============================================================================= -->
  <!-- FINGERS -->
  <!-- RIGHT HAND due to which finger is number 0 -->
  <!-- for LEFT HAND switch the sign of the **offset_origin_y** and **finger_angle_r** parameters-->
  <link name="hand_link_0.0_link">
    <visual>
      <geometry>
        <mesh filename="./../meshes/allegro/meshes/allegro/link_0.0.obj"/>
      </geometry>
      <material name="black"/>
    </visual>
    <collision>
      <geometry>
        <box size="0.0196 0.0275 0.0164"/>
      </geometry>
      <origin rpy="0 0 0" xyz="0 0 0.0082"/>
    </collision>
    <inertial>
      <mass value="0.0119"/>
      <origin rpy="0 0 0" xyz="0 0 0"/>
      <inertia ixx="1.01666658333e-06" ixy="0.0" ixz="0.0" iyy="6.47677333333e-07" iyz="0.0" izz="1.01666658333e-06"/>
    </inertial>
  </link>
  <joint name="joint_0.0" type="revolute">
    <axis xyz="0 0 1"/>
    <limit effort="0.35" lower="-0.47" upper="0.47" velocity="6.283"/>
    <parent link="hand_palm_link"/>
    <child link="hand_link_0.0_link"/>
    <origin rpy="0.08726646255 0 0" xyz="0 -0.0435 -0.001542"/>
  </joint>
  <link name="hand_link_1.0_link">
    <visual>
      <geometry>
        <mesh filename="./../meshes/allegro/meshes/allegro/link_1.0.obj"/>
      </geometry>
      <material name="black"/>
    </visual>
    <collision>
      <geometry>
        <box size="0.0196 0.0275 0.054"/>
      </geometry>
      <origin rpy="0 0 0" xyz="0 0 0.027"/>
    </collision>
    <inertial>
      <mass value="0.065"/>
      <origin rpy="0 0 0" xyz="0 0 0"/>
      <inertia ixx="7.95654166667e-05" ixy="1.7199e-05" ixz="8.75875e-06" iyy="2.47088833333e-05" iyz="2.413125e-05" izz="7.95654166667e-05"/>
    </inertial>
  </link>
  <joint name="joint_1.0" type="revolute">
    <limit effort="0.35" lower="-0.196" upper="1.61" velocity="6.283"/>
    <axis xyz="0 1 0"/>
    <parent link="hand_link_0.0_link"/>
    <child link="hand_link_1.0_link"/>
    <origin xyz="0 0 0.0164"/>
  </joint>

  <link name="finger_1_contact_1_link">
    <visual>
      <geometry>
        <box size="0.00125 0.017 0.065"/>
      </geometry>
      <material name="blue">
        <color rgba="0 0 1 1"/>
      </material>
    </visual>
    <collision>
      <geometry>
        <box size="0.00125 0.017 0.065"/>
      </geometry>
    </collision>
  </link>

  <joint name="finger_1_contact2_1" type="fixed" dont_collapse="true">
    <parent link="hand_link_1.0_link"/>
    <child link="finger_1_contact_1_link"/>
    <origin rpy="0 0 0" xyz="0.01 0 0.0275"/>
  </joint>

  <link name="hand_link_2.0_link">
    <visual>
      <geometry>
        <mesh filename="./../meshes/allegro/meshes/allegro/link_2.0.obj"/>
      </geometry>
      <material name="black"/>
    </visual>
    <collision>
      <geometry>
        <box size="0.0196 0.0275 0.0384"/>
      </geometry>
      <origin rpy="0 0 0" xyz="0 0 0.0192"/>
    </collision>
    <inertial>
      <mass value="0.0355"/>
      <origin rpy="0 0 0" xyz="0 0 0"/>
      <inertia ixx="2.63979183333e-05" ixy="6.67968e-06" ixz="4.783625e-06" iyy="1.34948516667e-05" iyz="9.372e-06" izz="2.63979183333e-05"/>
    </inertial>
  </link>
  <joint name="joint_2.0" type="revolute">
    <axis xyz="0 1 0"/>
    <limit effort="0.35" lower="-0.174" upper="1.709" velocity="6.283"/>
    <parent link="hand_link_1.0_link"/>
    <child link="hand_link_2.0_link"/>
    <origin xyz="0 0 0.054"/>
  </joint>

  <link name="finger_1_contact_2_link">
    <visual>
      <geometry>
        <box size="0.00125 0.017 0.0375"/>
      </geometry>
      <material name="blue">
        <color rgba="0 0 1 1"/>
      </material>
    </visual>
    <collision>
      <geometry>
        <box size="0.00125 0.017 0.0375"/>
      </geometry>
    </collision>
  </link>

  <joint name="finger_1_contact2_2" type="fixed" dont_collapse="true">
    <parent link="hand_link_2.0_link"/>
    <child link="finger_1_contact_2_link"/>
    <origin rpy="0 0 0" xyz="0.01 0 0.0325"/>
  </joint>

  <link name="hand_link_3.0_link">
    <visual>
      <geometry>
        <mesh filename="./../meshes/allegro/meshes/allegro/link_3.0.obj"/>
      </geometry>
      <material name="black"/>
    </visual>
    <collision>
      <geometry>
        <sphere radius="0.0001"/>
      </geometry>
      <origin rpy="0 0 0" xyz="0 0 0.01335"/>
    </collision>
    <inertial>
      <mass value="0.0096"/>
      <origin rpy="0 0 0" xyz="0 0 0"/>
      <inertia ixx="4.701248e-06" ixy="1.255968e-06" ixz="1.2936e-06" iyy="3.649312e-06" iyz="1.7622e-06" izz="4.701248e-06"/>
    </inertial>
  </link>
  <joint name="joint_3.0" type="revolute">
    <axis xyz="0 1 0"/>
    <limit effort="0.35" lower="-0.227" upper="1.618" velocity="6.283"/>
    <parent link="hand_link_2.0_link"/>
    <child link="hand_link_3.0_link"/>
    <origin xyz="0 0 0.0384"/>
  </joint>

  <!-- <link name="finger_1_contact_3">
    <visual>
      <geometry>
        <box size="0.00125 0.022 0.0375"/>
      </geometry>
      <material name="blue">
        <color rgba="0 0 1 1"/>
      </material>
    </visual>
    <collision>
      <geometry>
        <box size="0.00125 0.022 0.0375"/>
      </geometry>
    </collision>
  </link>

  <joint name="finger_1_contact2_3" type="fixed" dont_collapse="true">
    <parent link="hand_link_3.0_link"/>
    <child link="finger_1_contact_3"/>
    <origin rpy="0 0 0" xyz="0.01 0 -0.005"/>
  </joint> -->

  <link name="hand_link_3.0_link_tip_link">
    <visual>
      <geometry>
        <mesh filename="./../meshes/allegro/meshes/allegro/digit.obj"/>
      </geometry>
      <origin rpy="0 0 0" xyz="-0.02 0.000 -0.015"/>
      <material name="white">
        <color rgba=".9 .9 .9 1"/>
      </material>
    </visual>
    <collision>
      <geometry>
        <sphere radius="0.01235"/>
      </geometry>
      <origin rpy="0 0 0" xyz="0.000 0.000 0"/>
    </collision>
    <inertial>
      <mass value="0.0168"/>
      <origin rpy="0 0 0" xyz="0 0 0"/>
      <inertia ixx="9.68e-07" ixy="0" ixz="0" iyy="9.68e-07" iyz="0" izz="9.68e-07"/>
    </inertial>
  </link>
  <joint name="joint_3.0_tip_link" type="fixed" dont_collapse="true">
    <parent link="hand_link_3.0_link"/>
    <child link="hand_link_3.0_link_tip_link"/>
    <origin rpy="0 0 0" xyz="0.02 0 0.03"/>
  </joint>

  <link name="finger_1_contact_3_tip_link">
    <visual>
      <geometry>
        <box size="0.00075 0.02 0.02"/>
      </geometry>
      <material name="blue">
        <color rgba="0 0 1 1"/>
      </material>
    </visual>
    <collision>
      <geometry>
        <box size="0.00075 0.02 0.02"/>
      </geometry>
    </collision>
  </link>

  <joint name="finger_1_contact2_3_tip" type="fixed" dont_collapse="true">
    <parent link="hand_link_3.0_link_tip_link"/>
    <child link="finger_1_contact_3_tip_link"/>
    <origin rpy="0 0 0" xyz="0 0 0"/>
  </joint>

  <link name="hand_link_4.0_link">
    <visual>
      <geometry>
        <mesh filename="./../meshes/allegro/meshes/allegro/link_0.0.obj"/>
      </geometry>
      <material name="black"/>
    </visual>
    <collision>
      <geometry>
        <box size="0.0196 0.0275 0.0164"/>
      </geometry>
      <origin rpy="0 0 0" xyz="0 0 0.0082"/>
    </collision>
    <inertial>
      <mass value="0.0119"/>
      <origin rpy="0 0 0" xyz="0 0 0"/>
      <inertia ixx="1.01666658333e-06" ixy="0.0" ixz="0.0" iyy="6.47677333333e-07" iyz="0.0" izz="1.01666658333e-06"/>
    </inertial>
  </link>
  <joint name="joint_4.0" type="revolute">
    <axis xyz="0 0 1"/>
    <limit effort="0.35" lower="-0.47" upper="0.47" velocity="6.283"/>
    <parent link="hand_palm_link"/>
    <child link="hand_link_4.0_link"/>
    <origin rpy="0.0 0 0" xyz="0 0 0.0007"/>
  </joint>
  <link name="hand_link_5.0_link">
    <visual>
      <geometry>
        <mesh filename="./../meshes/allegro/meshes/allegro/link_1.0.obj"/>
      </geometry>
      <material name="black"/>
    </visual>
    <collision>
      <geometry>
        <box size="0.0196 0.0275 0.054"/>
      </geometry>
      <origin rpy="0 0 0" xyz="0 0 0.027"/>
    </collision>
    <inertial>
      <mass value="0.065"/>
      <origin rpy="0 0 0" xyz="0 0 0"/>
      <inertia ixx="7.95654166667e-05" ixy="1.7199e-05" ixz="8.75875e-06" iyy="2.47088833333e-05" iyz="2.413125e-05" izz="7.95654166667e-05"/>
    </inertial>
  </link>
  <joint name="joint_5.0" type="revolute">
    <limit effort="0.35" lower="-0.196" upper="1.61" velocity="6.283"/>
    <axis xyz="0 1 0"/>
    <parent link="hand_link_4.0_link"/>
    <child link="hand_link_5.0_link"/>
    <origin xyz="0 0 0.0164"/>
  </joint>

  <link name="finger_2_contact_5_link">
    <visual>
      <geometry>
        <box size="0.00125 0.017 0.065"/>
      </geometry>
      <material name="blue">
        <color rgba="0 0 1 1"/>
      </material>
    </visual>
    <collision>
      <geometry>
        <box size="0.00125 0.017 0.065"/>
      </geometry>
    </collision>
  </link>

  <joint name="finger_2_contact5_1" type="fixed" dont_collapse="true">
    <parent link="hand_link_5.0_link"/>
    <child link="finger_2_contact_5_link"/>
    <origin rpy="0 0 0" xyz="0.01 0 0.0275"/>
  </joint>

  <link name="hand_link_6.0_link">
    <visual>
      <geometry>
        <mesh filename="./../meshes/allegro/meshes/allegro/link_2.0.obj"/>
      </geometry>
      <material name="black"/>
    </visual>
    <collision>
      <geometry>
        <box size="0.0196 0.0275 0.0384"/>
      </geometry>
      <origin rpy="0 0 0" xyz="0 0 0.0192"/>
    </collision>
    <inertial>
      <mass value="0.0355"/>
      <origin rpy="0 0 0" xyz="0 0 0"/>
      <inertia ixx="2.63979183333e-05" ixy="6.67968e-06" ixz="4.783625e-06" iyy="1.34948516667e-05" iyz="9.372e-06" izz="2.63979183333e-05"/>
    </inertial>
  </link>
  <joint name="joint_6.0" type="revolute">
    <axis xyz="0 1 0"/>
    <limit effort="0.35" lower="-0.174" upper="1.709" velocity="6.283"/>
    <parent link="hand_link_5.0_link"/>
    <child link="hand_link_6.0_link"/>
    <origin xyz="0 0 0.054"/>
  </joint>

  <link name="finger_2_contact_6_link">
    <visual>
      <geometry>
        <box size="0.00125 0.017 0.0375"/>
      </geometry>
      <material name="blue">
        <color rgba="0 0 1 1"/>
      </material>
    </visual>
    <collision>
      <geometry>
        <box size="0.00125 0.017 0.0375"/>
      </geometry>
    </collision>
  </link>

  <joint name="finger_2_contact6_2" type="fixed" dont_collapse="true">
    <parent link="hand_link_6.0_link"/>
    <child link="finger_2_contact_6_link"/>
    <origin rpy="0 0 0" xyz="0.01 0 0.0325"/>
  </joint>

  <link name="hand_link_7.0_link">
    <visual>
      <geometry>
        <mesh filename="./../meshes/allegro/meshes/allegro/link_3.0.obj"/>
      </geometry>
      <material name="black"/>
    </visual>
    <collision>
      <geometry>
        <sphere radius="0.0001"/>
      </geometry>
    </collision>
    <inertial>
      <mass value="0.0096"/>
      <origin rpy="0 0 0" xyz="0 0 0"/>
      <inertia ixx="4.701248e-06" ixy="1.255968e-06" ixz="1.2936e-06" iyy="3.649312e-06" iyz="1.7622e-06" izz="4.701248e-06"/>
    </inertial>
  </link>
  <joint name="joint_7.0" type="revolute">
    <axis xyz="0 1 0"/>
    <limit effort="0.35" lower="-0.227" upper="1.618" velocity="6.283"/>
    <parent link="hand_link_6.0_link"/>
    <child link="hand_link_7.0_link"/>
    <origin xyz="0 0 0.0384"/>
  </joint>

  <!-- <link name="finger_2_contact_7">
    <visual>
      <geometry>
        <box size="0.00125 0.022 0.0375"/>
      </geometry>
      <material name="blue">
        <color rgba="0 0 1 1"/>
      </material>
    </visual>
    <collision>
      <geometry>
        <box size="0.00125 0.022 0.0375"/>
      </geometry>
    </collision>
  </link>

  <joint name="finger_2_contact2_7" type="fixed" dont_collapse="true">
    <parent link="hand_link_7.0_link"/>
    <child link="finger_2_contact_7"/>
    <origin rpy="0 0 0" xyz="0.01 0 -0.005"/>
  </joint> -->

  <link name="hand_link_7.0_link_tip_link">
    <visual>
      <geometry>
        <mesh filename="./../meshes/allegro/meshes/allegro/digit.obj"/>
      </geometry>
      <origin rpy="0 0 0" xyz="-0.02 0.000 -0.015"/>
      <material name="white">
        <color rgba=".9 .9 .9 1"/>
      </material>
    </visual>
    <collision>
      <geometry>
        <sphere radius="0.01235"/>
      </geometry>
    </collision>
    <inertial>
      <mass value="0.0168"/>
      <origin rpy="0 0 0" xyz="0 0 0"/>
      <inertia ixx="9.68e-07" ixy="0" ixz="0" iyy="9.68e-07" iyz="0" izz="9.68e-07"/>
    </inertial>
  </link>
  <joint name="joint_7.0_tip_link" type="fixed" dont_collapse="true">
    <parent link="hand_link_7.0_link"/>
    <child link="hand_link_7.0_link_tip_link"/>
    <origin rpy="0 0 0" xyz="0.02 0 0.03"/>
  </joint>

  <link name="finger_2_contact_7_tip_link">
    <visual>
      <geometry>
        <box size="0.00075 0.02 0.02"/>
      </geometry>
      <material name="blue">
        <color rgba="0 0 1 1"/>
      </material>
    </visual>
    <collision>
      <geometry>
        <box size="0.00075 0.02 0.02"/>
      </geometry>
    </collision>
  </link>

  <joint name="finger_2_contact2_7_tip" type="fixed" dont_collapse="true">
    <parent link="hand_link_7.0_link_tip_link"/>
    <child link="finger_2_contact_7_tip_link"/>
    <origin rpy="0 0 0" xyz="0 0 0"/>
  </joint>

  <link name="hand_link_8.0_link">
    <visual>
      <geometry>
        <mesh filename="./../meshes/allegro/meshes/allegro/link_0.0.obj"/>
      </geometry>
      <material name="black"/>
    </visual>
    <collision>
      <geometry>
        <box size="0.0196 0.0275 0.0164"/>
      </geometry>
      <origin rpy="0 0 0" xyz="0 0 0.0082"/>
    </collision>
    <inertial>
      <mass value="0.0119"/>
      <origin rpy="0 0 0" xyz="0 0 0"/>
      <inertia ixx="1.01666658333e-06" ixy="0.0" ixz="0.0" iyy="6.47677333333e-07" iyz="0.0" izz="1.01666658333e-06"/>
    </inertial>
  </link>
  <joint name="joint_8.0" type="revolute">
    <axis xyz="0 0 1"/>
    <limit effort="0.35" lower="-0.47" upper="0.47" velocity="6.283"/>
    <parent link="hand_palm_link"/>
    <child link="hand_link_8.0_link"/>
    <origin rpy="-0.08726646255 0 0" xyz="0 0.0435 -0.001542"/>
  </joint>
  <link name="hand_link_9.0_link">
    <visual>
      <geometry>
        <mesh filename="./../meshes/allegro/meshes/allegro/link_1.0.obj"/>
      </geometry>
      <material name="black"/>
    </visual>
    <collision>
      <geometry>
        <box size="0.0196 0.0275 0.054"/>
      </geometry>
      <origin rpy="0 0 0" xyz="0 0 0.027"/>
    </collision>
    <inertial>
      <mass value="0.065"/>
      <origin rpy="0 0 0" xyz="0 0 0"/>
      <inertia ixx="7.95654166667e-05" ixy="1.7199e-05" ixz="8.75875e-06" iyy="2.47088833333e-05" iyz="2.413125e-05" izz="7.95654166667e-05"/>
    </inertial>
  </link>
  <joint name="joint_9.0" type="revolute">
    <limit effort="0.35" lower="-0.196" upper="1.61" velocity="6.283"/>
    <axis xyz="0 1 0"/>
    <parent link="hand_link_8.0_link"/>
    <child link="hand_link_9.0_link"/>
    <origin xyz="0 0 0.0164"/>
  </joint>

  <link name="finger_3_contact_9_link">
    <visual>
      <geometry>
        <box size="0.00125 0.017 0.065"/>
      </geometry>
      <material name="blue">
        <color rgba="0 0 1 1"/>
      </material>
    </visual>
    <collision>
      <geometry>
        <box size="0.00125 0.017 0.065"/>
      </geometry>
    </collision>
  </link>

  <joint name="finger_3_contact9_1" type="fixed" dont_collapse="true">
    <parent link="hand_link_9.0_link"/>
    <child link="finger_3_contact_9_link"/>
    <origin rpy="0 0 0" xyz="0.01 0 0.0275"/>
  </joint>

  <link name="hand_link_10._link">
    <visual>
      <geometry>
        <mesh filename="./../meshes/allegro/meshes/allegro/link_2.0.obj"/>
      </geometry>
      <material name="black"/>
    </visual>
    <collision>
      <geometry>
        <box size="0.0196 0.0275 0.0384"/>
      </geometry>
      <origin rpy="0 0 0" xyz="0 0 0.0192"/>
    </collision>
    <inertial>
      <mass value="0.0355"/>
      <origin rpy="0 0 0" xyz="0 0 0"/>
      <inertia ixx="2.63979183333e-05" ixy="6.67968e-06" ixz="4.783625e-06" iyy="1.34948516667e-05" iyz="9.372e-06" izz="2.63979183333e-05"/>
    </inertial>
  </link>
  <joint name="joint_10.0" type="revolute">
    <axis xyz="0 1 0"/>
    <limit effort="0.35" lower="-0.174" upper="1.709" velocity="6.283"/>
    <parent link="hand_link_9.0_link"/>
    <child link="hand_link_10._link"/>
    <origin xyz="0 0 0.054"/>
  </joint>

  <link name="finger_3_contact_10_link">
    <visual>
      <geometry>
        <box size="0.00125 0.017 0.0375"/>
      </geometry>
      <material name="blue">
        <color rgba="0 0 1 1"/>
      </material>
    </visual>
    <collision>
      <geometry>
        <box size="0.00125 0.017 0.0375"/>
      </geometry>
    </collision>
  </link>

  <joint name="finger_3_contact10_2" type="fixed" dont_collapse="true">
    <parent link="hand_link_10._link"/>
    <child link="finger_3_contact_10_link"/>
    <origin rpy="0 0 0" xyz="0.01 0 0.0325"/>
  </joint>

  <link name="hand_link_11._link">
    <visual>
      <geometry>
        <mesh filename="./../meshes/allegro/meshes/allegro/link_3.0.obj"/>
      </geometry>
      <material name="black"/>
    </visual>
    <collision>
      <geometry>
        <sphere radius="0.0001"/>
      </geometry>
    </collision>
    <inertial>
      <mass value="0.0096"/>
      <origin rpy="0 0 0" xyz="0 0 0"/>
      <inertia ixx="4.701248e-06" ixy="1.255968e-06" ixz="1.2936e-06" iyy="3.649312e-06" iyz="1.7622e-06" izz="4.701248e-06"/>
    </inertial>
  </link>
  <joint name="joint_11.0" type="revolute">
    <axis xyz="0 1 0"/>
    <limit effort="0.35" lower="-0.227" upper="1.618" velocity="6.283"/>
    <parent link="hand_link_10._link"/>
    <child link="hand_link_11._link"/>
    <origin xyz="0 0 0.0384"/>
  </joint>

  <!-- <link name="finger_3_contact_11">
    <visual>
      <geometry>
        <box size="0.00125 0.022 0.0375"/>
      </geometry>
      <material name="blue">
        <color rgba="0 0 1 1"/>
      </material>
    </visual>
    <collision>
      <geometry>
        <box size="0.00125 0.022 0.0375"/>
      </geometry>
    </collision>
  </link>

  <joint name="finger_3_contact2_11" type="fixed" dont_collapse="true">
    <parent link="hand_link_11._link"/>
    <child link="finger_3_contact_11"/>
    <origin rpy="0 0 0" xyz="0.01 0 -0.005"/>
  </joint> -->

  <link name="hand_link_11._link_tip_link">
    <visual>
      <geometry>
        <mesh filename="./../meshes/allegro/meshes/allegro/digit.obj"/>
      </geometry>
      <origin rpy="0 0 0" xyz="-0.02 0.000 -0.015"/>
      <material name="white">
        <color rgba=".9 .9 .9 1"/>
      </material>
    </visual>
    <collision>
      <geometry>
        <sphere radius="0.01235"/>
      </geometry>
    </collision>
    <inertial>
      <mass value="0.0168"/>
      <origin rpy="0 0 0" xyz="0 0 0"/>
      <inertia ixx="9.68e-07" ixy="0" ixz="0" iyy="9.68e-07" iyz="0" izz="9.68e-07"/>
    </inertial>
  </link>
  <joint name="joint_11.0_tip_link" type="fixed" dont_collapse="true">
    <parent link="hand_link_11._link"/>
    <child link="hand_link_11._link_tip_link"/>
    <origin rpy="0 0 0" xyz="0.02 0 0.03"/>
  </joint>

  <link name="finger_3_contact_11_tip_link">
    <visual>
      <geometry>
        <box size="0.00075 0.02 0.02"/>
      </geometry>
      <material name="blue">
        <color rgba="0 0 1 1"/>
      </material>
    </visual>
    <collision>
      <geometry>
        <box size="0.00075 0.02 0.02"/>
      </geometry>
    </collision>
  </link>

  <joint name="finger_3_contact2_11_tip" type="fixed" dont_collapse="true">
    <parent link="hand_link_11._link_tip_link"/>
    <child link="finger_3_contact_11_tip_link"/>
    <origin rpy="0 0 0" xyz="0 0 0"/>
  </joint>

  <!-- THUMB -->
  <link name="hand_link_12._link">
    <visual>
      <geometry>
        <!-- RIGHT -->
        <!-- <mesh filename="./../meshes/allegro/meshes/allegro/link_12.0_right.obj"/> -->
        <!-- LEFT -->
        <mesh filename="./../meshes/allegro/meshes/allegro/link_12.0_left.obj" />
      </geometry>
      <material name="black">
        <color rgba=".2 .2 .2 1"/>
      </material>
    </visual>
    <collision>
      <geometry>
        <box size="0.0358 0.034 0.0455"/>
      </geometry>
      <!-- RIGHT -->
      <!-- <origin rpy="0 0 0" xyz="-0.0179 0.009 0.0145"/> -->
      <!-- LEFT -->
      <origin rpy="0 0 0" xyz="-0.0179 -0.09 0.145"/>
    </collision>
    <inertial>
      <mass value="0.0176"/>
      <origin rpy="0 0 0" xyz="0 0 0"/>
      <inertia ixx="1.89273333333e-5" ixy="7.16716e-06" ixz="5.35568e-06" iyy="1.43008213333e-05" iyz="6.8068e-06" izz="1.89273333333e-05"/>
    </inertial>
  </link>
  <joint name="joint_12.0" type="revolute">
    <axis xyz="1 0 0"/>
    <limit effort="0.35" lower="0.263" upper="1.396" velocity="6.283"/>
    <parent link="hand_palm_link"/>
    <child link="hand_link_12._link"/>
    <origin rpy="0 -1.65806278845 1.5707963259" xyz="-0.0182 -0.019333 -0.045987"/>
  </joint>
  <link name="hand_link_13._link">
    <visual>
      <geometry>
        <mesh filename="./../meshes/allegro/meshes/allegro/link_13.0.obj"/>
      </geometry>
      <material name="black">
        <color rgba=".2 .2 .2 1"/>
      </material>
    </visual>
    <collision>
      <geometry>
        <box size="0.0196 0.0275 0.0177"/>
      </geometry>
      <origin rpy="0 0 0" xyz="0 0 0.00885"/>
    </collision>
    <inertial>
      <mass value="0.0119"/>
      <origin rpy="0 0 0" xyz="0 0 0"/>
      <inertia ixx="4.24250866667e-06" ixy="1.032087e-06" ixz="1.603525e-06" iyy="4.52362633333e-06" iyz="1.44808125e-06" izz="4.24250866667e-06"/>
    </inertial>
  </link>
  <joint name="joint_13.0" type="revolute">
    <axis xyz="0 0 -1"/>
    <limit effort="0.35" lower="-0.105" upper="1.163" velocity="6.283"/>
    <parent link="hand_link_12._link"/>
    <child link="hand_link_13._link"/>
    <!-- LEFT -->
    <origin xyz="-0.027 -0.005 0" rpy="0 0 -1.57"/> <!-- -0.027 -0.005 -0.0399 -->
    <!-- RIGHT -->
    <!-- <origin xyz="-0.027 0.005 0.0399"/> -->
  </joint>
  <link name="hand_link_14._link">
    <visual>
      <geometry>
        <mesh filename="./../meshes/allegro/meshes/allegro/link_14.0.obj"/>
      </geometry>
      <material name="black">
      </material>
    </visual>
    <collision>
      <geometry>
        <box size="0.0196 0.0275 0.0514"/>
      </geometry>
      <origin rpy="0 0 0" xyz="0 0 0.0257"/>
    </collision>
    <inertial>
      <mass value="0.038"/>
      <origin rpy="0 0 0" xyz="0 0 0"/>
      <inertia ixx="4.30439933333e-05" ixy="9.57068e-06" ixz="5.1205e-06" iyy="1.44451933333e-05" iyz="1.342825e-05" izz="4.30439933333e-05"/>
    </inertial>
  </link>
  <joint name="joint_14.0" type="revolute">
    <axis xyz="0 1 0"/>
    <limit effort="0.35" lower="-0.189" upper="1.644" velocity="6.283"/>
    <parent link="hand_link_13._link"/>
    <child link="hand_link_14._link"/>
    <origin xyz="0 0 0.0177"/>
  </joint>

<link name="finger_4_contact_14_link">
    <visual>
      <geometry>
        <box size="0.00125 0.022 0.0375"/>
      </geometry>
      <material name="blue">
        <color rgba="0 0 1 1"/>
      </material>
    </visual>
    <collision>
      <geometry>
        <box size="0.00125 0.022 0.0375"/>
      </geometry>
    </collision>
  </link>

  <joint name="finger_4_contact2_14" type="fixed" dont_collapse="true">
    <parent link="hand_link_14._link"/>
    <child link="finger_4_contact_14_link"/>
    <origin rpy="0 0 0" xyz="0.01 0 0.005"/>
  </joint>

  <link name="hand_link_15._link">
    <visual>
      <geometry>
        <mesh filename="./../meshes/allegro/meshes/allegro/link_15.0.obj"/>
      </geometry>
      <material name="black">
    	</material>
    </visual>
    <collision>
      <geometry>
        <sphere radius="0.0001"/>
      </geometry>
      <origin rpy="0 0 0" xyz="0 0 0.02115"/>
    </collision>
    <inertial>
      <mass value="0.0388"/>
      <origin rpy="0 0 0" xyz="0 0 0"/>
      <inertia ixx="3.29223173333e-05" ixy="8.042076e-06" ixz="5.2283e-06" iyy="1.47493026667e-5" iyz="1.1283525e-5" izz="3.29223173333e-05"/>
    </inertial>
  </link>
  <joint name="joint_15.0" type="revolute">
    <axis xyz="0 1 0"/>
    <limit effort="0.35" lower="-0.162" upper="1.719" velocity="6.283"/>
    <parent link="hand_link_14._link"/>
    <child link="hand_link_15._link"/>
    <origin xyz="0 0 0.0514"/>
  </joint>

  <link name="finger_4_contact_15_link">
    <visual>
      <geometry>
        <box size="0.00125 0.022 0.035"/>
      </geometry>
      <material name="blue">
        <color rgba="0 0 1 1"/>
      </material>
    </visual>
    <collision>
      <geometry>
        <box size="0.00125 0.022 0.035"/>
      </geometry>
    </collision>
  </link>

  <joint name="finger_4_contact2_15" type="fixed" dont_collapse="true">
    <parent link="hand_link_15._link"/>
    <child link="finger_4_contact_15_link"/>
    <origin rpy="0 0 0" xyz="0.01 0 0.005"/>
  </joint>

  <link name="hand_link_15._link_tip_link">
    <visual>
      <geometry>
        <mesh filename="./../meshes/allegro/meshes/allegro/digit.obj"/>
      </geometry>
      <origin rpy="0 0 0" xyz="-0.02 0.000 -0.015"/>
      <material name="white">
        <color rgba=".9 .9 .9 1"/>
      </material>
    </visual>
    <collision>
      <geometry>
        <sphere radius="0.01235"/>
      </geometry>
    </collision>
    <inertial>
      <mass value="0.0168"/>
      <origin rpy="0 0 0" xyz="0 0 0"/>
      <inertia ixx="9.68e-07" ixy="0" ixz="0" iyy="9.68e-07" iyz="0" izz="9.68e-07"/>
    </inertial>
  </link>
  <joint name="joint_15.0_tip_link" type="fixed" dont_collapse="true">
    <parent link="hand_link_15._link"/>
    <child link="hand_link_15._link_tip_link"/>
    <origin rpy="0 0 0" xyz="0.02 0 0.0455"/>
  </joint>

  <link name="finger_4_contact_15_tip_link">
    <visual>
      <geometry>
        <box size="0.00075 0.02 0.02"/>
      </geometry>
      <material name="blue">
        <color rgba="0 0 1 1"/>
      </material>
    </visual>
    <collision>
      <geometry>
        <box size="0.00075 0.02 0.02"/>
      </geometry>
    </collision>
  </link>

  <joint name="finger_4_contact2_15_tip" type="fixed" dont_collapse="true">
    <parent link="hand_link_15._link_tip_link"/>
    <child link="finger_4_contact_15_tip_link"/>
    <origin rpy="0 0 0" xyz="0.0 0 0.0"/>
  </joint>



  

  <joint name="palm_2_ur" type="fixed" dont_collapse="true">
    <parent link="tool_frame"/>
    <child link="hand_palm_link"/>
    <origin rpy="0 0 5.5" xyz="0.0 0 0.1175"/>
  </joint>
</robot>
