<?xml version="1.0" ?>
<!-- =================================================================================== -->
<!-- |    This document was autogenerated by xacro from ur.urdf.xacro                  | -->
<!-- |    EDITING THIS FILE BY HAND IS NOT RECOMMENDED                                 | -->
<!-- =================================================================================== -->
<robot name="robot">
  <!--
    Base UR robot series xacro macro.

    NOTE this is NOT a URDF. It cannot directly be loaded by consumers
    expecting a flattened '.urdf' file. See the top-level '.xacro' for that
    (but note that .xacro must still be processed by the xacro command).

    This file models the base kinematic chain of a UR robot, which then gets
    parameterised by various configuration files to convert it into a UR3(e),
    UR5(e), UR10(e) or UR16e.

    NOTE the default kinematic parameters (i.e., link lengths, frame locations,
    offsets, etc) do not correspond to any particular robot. They are defaults
    only. There WILL be non-zero offsets between the Forward Kinematics results
    in TF (i.e., robot_state_publisher) and the values reported by the Teach
    Pendant.

    For accurate (and robot-specific) transforms, the 'kinematics_parameters_file'
    parameter MUST point to a .yaml file containing the appropriate values for
    the targeted robot.

    If using the UniversalRobots/Universal_Robots_ROS_Driver, follow the steps
    described in the readme of that repository to extract the kinematic
    calibration from the controller and generate the required .yaml file.

    Main author of the migration to yaml configs Ludovic Delval.

    Contributors to previous versions (in no particular order)

     - Denis Stogl
     - Lovro Ivanov
     - Felix Messmer
     - Kelsey Hawkins
     - Wim Meeussen
     - Shaun Edwards
     - Nadia Hammoudeh Garcia
     - Dave Hershberger
     - G. vd. Hoorn
     - Philip Long
     - Dave Coleman
     - Miguel Prada
     - Mathias Luedtke
     - Marcel Schnirring
     - Felix von Drigalski
     - Felix Exner
     - Jimmy Da Silva
     - Ajit Krisshna N L
     - Muhammad Asif Rana
  -->
  <!--
    NOTE the macro defined in this file is NOT part of the public API of this
          package. Users CANNOT rely on this file being available, or stored in
          this location. Nor can they rely on the existence of the macro.
  -->
  <!-- create link fixed to the "world" -->
  <link name="world"/>
  

  <link name="base_link"/>
  <link name="base_link_inertia">
    <visual>
      <origin rpy="0 0 3.141592653589793" xyz="0 0 0"/>
      <geometry>
        <mesh filename="./../meshes/ur5e/visual/base.dae"/>
      </geometry>
    </visual>
    <collision>
      <origin rpy="0 0 3.141592653589793" xyz="0 0 0"/>
      <geometry>
        <mesh filename="./../meshes/ur5e/collision/base.stl"/>
      </geometry>
    </collision>
    <inertial>
      <mass value="4.0"/>
      <origin rpy="0 0 0" xyz="0 0 0"/>
      <inertia ixx="0.00443333156" ixy="0.0" ixz="0.0" iyy="0.00443333156" iyz="0.0" izz="0.0072"/>
    </inertial>
  </link>
  <link name="shoulder_link">
    <visual>
      <origin rpy="0 0 3.141592653589793" xyz="0 0 0"/>
      <geometry>
        <mesh filename="./../meshes/ur5e/visual/shoulder.dae"/>
      </geometry>
    </visual>
    <collision>
      <origin rpy="0 0 3.141592653589793" xyz="0 0 0"/>
      <geometry>
        <mesh filename="./../meshes/ur5e/collision/shoulder.stl"/>
      </geometry>
    </collision>
    <inertial>
      <mass value="3.761"/>
      <origin rpy="0 0 0" xyz="0.0 -0.00193 -0.02561"/>
      <inertia ixx="0.010267499999999999" ixy="0" ixz="0" iyy="0.010267499999999999" iyz="0" izz="0.00666"/>
    </inertial>
  </link>
  <link name="upper_arm_link">
    <visual>
      <origin rpy="1.5707963267948966 0 -1.5707963267948966" xyz="0 0 0.138"/>
      <geometry>
        <mesh filename="./../meshes/ur5e/visual/upperarm.dae"/>
      </geometry>
    </visual>
    <collision>
      <origin rpy="1.5707963267948966 0 -1.5707963267948966" xyz="0 0 0.138"/>
      <geometry>
        <mesh filename="./../meshes/ur5e/collision/upperarm.stl"/>
      </geometry>
    </collision>
    <inertial>
      <mass value="8.058"/>
      <origin rpy="0 1.570796326794897 0" xyz="-0.2125 0.0 0.11336"/>
      <inertia ixx="0.13388583541666665" ixy="0" ixz="0" iyy="0.13388583541666665" iyz="0" izz="0.0151074"/>
    </inertial>
  </link>
  <link name="forearm_link">
    <visual>
      <origin rpy="1.5707963267948966 0 -1.5707963267948966" xyz="0 0 0.007"/>
      <geometry>
        <mesh filename="./../meshes/ur5e/visual/forearm.dae"/>
      </geometry>
    </visual>
    <collision>
      <origin rpy="1.5707963267948966 0 -1.5707963267948966" xyz="0 0 0.007"/>
      <geometry>
        <mesh filename="./../meshes/ur5e/collision/forearm.stl"/>
      </geometry>
    </collision>
    <inertial>
      <mass value="2.846"/>
      <origin rpy="0 1.570796326794897 0" xyz="-0.2422 0.0 0.0265"/>
      <inertia ixx="0.03120936758333333" ixy="0" ixz="0" iyy="0.03120936758333333" iyz="0" izz="0.004095"/>
    </inertial>
  </link>
  <link name="wrist_1_link">
    <visual>
      <origin rpy="1.5707963267948966 0 0" xyz="0 0 -0.127"/>
      <geometry>
        <mesh filename="./../meshes/ur5e/visual/wrist1.dae"/>
      </geometry>
    </visual>
    <collision>
      <origin rpy="1.5707963267948966 0 0" xyz="0 0 -0.127"/>
      <geometry>
        <mesh filename="./../meshes/ur5e/collision/wrist1.stl"/>
      </geometry>
    </collision>
    <inertial>
      <mass value="1.37"/>
      <origin rpy="0 0 0" xyz="0.0 -0.01634 -0.0018"/>
      <inertia ixx="0.0025599" ixy="0" ixz="0" iyy="0.0025599" iyz="0" izz="0.0021942"/>
    </inertial>
  </link>
  <link name="wrist_2_link">
    <visual>
      <origin rpy="0 0 0" xyz="0 0 -0.0997"/>
      <geometry>
        <mesh filename="./../meshes/ur5e/visual/wrist2.dae"/>
      </geometry>
    </visual>
    <collision>
      <origin rpy="0 0 0" xyz="0 0 -0.0997"/>
      <geometry>
        <mesh filename="./../meshes/ur5e/collision/wrist2.stl"/>
      </geometry>
    </collision>
    <inertial>
      <mass value="1.3"/>
      <origin rpy="0 0 0" xyz="0.0 0.01634 -0.0018"/>
      <inertia ixx="0.0025599" ixy="0" ixz="0" iyy="0.0025599" iyz="0" izz="0.0021942"/>
    </inertial>
  </link>
  <link name="wrist_3_link">
    <visual>
      <origin rpy="1.5707963267948966 0 0" xyz="0 0 -0.0989"/>
      <geometry>
        <mesh filename="./../meshes/ur5e/visual/wrist3.dae"/>
      </geometry>
    </visual>
    <collision>
      <origin rpy="1.5707963267948966 0 0" xyz="0 0 -0.0989"/>
      <geometry>
        <mesh filename="./../meshes/ur5e/collision/wrist3.stl"/>
      </geometry>
    </collision>
    <inertial>
      <mass value="0.365"/>
      <origin rpy="0 0 0" xyz="0.0 0.0 -0.001159"/>
      <inertia ixx="9.890414008333333e-05" ixy="0" ixz="0" iyy="9.890414008333333e-05" iyz="0" izz="0.0001321171875"/>
    </inertial>
  </link>
  <!-- base_joint fixes base_link to the environment -->
  <joint name="base_joint" type="fixed" dont_collapse="true">
    <origin rpy="0 0 0" xyz="0 0 0"/>
    <parent link="world"/>
    <child link="base_link"/>
  </joint>
  <!-- joints - main serial chain -->
  <joint name="base_link-base_link_inertia" type="fixed" dont_collapse="true">
    <parent link="base_link"/>
    <child link="base_link_inertia"/>
    <!-- 'base_link' is REP-103 aligned (so X+ forward), while the internal
           frames of the robot/controller have X+ pointing backwards.
           Use the joint between 'base_link' and 'base_link_inertia' (a dummy
           link/frame) to introduce the necessary rotation over Z (of pi rad).
      -->
    <origin rpy="0 0 3.141592653589793" xyz="0 0 0"/>
  </joint>
  <joint name="arm_shoulder_pan_joint" type="revolute">
    <parent link="base_link_inertia"/>
    <child link="shoulder_link"/>
    <origin rpy="0 0 0" xyz="0 0 0.1625"/>
    <axis xyz="0 0 1"/>
    <limit effort="150.0" lower="-6.283185307179586" upper="6.283185307179586" velocity="3.141592653589793"/>
    <dynamics damping="0" friction="0"/>
  </joint>
  <joint name="arm_shoulder_lift_joint" type="revolute">
    <parent link="shoulder_link"/>
    <child link="upper_arm_link"/>
    <origin rpy="1.570796327 0 0" xyz="0 0 0"/>
    <axis xyz="0 0 1"/>
    <limit effort="150.0" lower="-6.283185307179586" upper="6.283185307179586" velocity="3.141592653589793"/>
    <dynamics damping="0" friction="0"/>
  </joint>
  <joint name="arm_elbow_joint" type="revolute">
    <parent link="upper_arm_link"/>
    <child link="forearm_link"/>
    <origin rpy="0 0 0" xyz="-0.425 0 0"/>
    <axis xyz="0 0 1"/>
    <limit effort="150.0" lower="-3.141592653589793" upper="3.141592653589793" velocity="3.141592653589793"/>
    <dynamics damping="0" friction="0"/>
  </joint>
  <joint name="arm_wrist_1_joint" type="revolute">
    <parent link="forearm_link"/>
    <child link="wrist_1_link"/>
    <origin rpy="0 0 0" xyz="-0.3922 0 0.1333"/>
    <axis xyz="0 0 1"/>
    <limit effort="28.0" lower="-6.283185307179586" upper="6.283185307179586" velocity="3.141592653589793"/>
    <dynamics damping="0" friction="0"/>
  </joint>
  <joint name="arm_wrist_2_joint" type="revolute">
    <parent link="wrist_1_link"/>
    <child link="wrist_2_link"/>
    <origin rpy="1.570796327 0 0" xyz="0 -0.0997 -2.044881182297852e-11"/>
    <axis xyz="0 0 1"/>
    <limit effort="28.0" lower="-6.283185307179586" upper="6.283185307179586" velocity="3.141592653589793"/>
    <dynamics damping="0" friction="0"/>
  </joint>
  <joint name="arm_wrist_3_joint" type="continuous">
    <parent link="wrist_2_link"/>
    <child link="wrist_3_link"/>
    <origin rpy="1.570796326589793 3.141592653589793 3.141592653589793" xyz="0 0.0996 -2.042830148012698e-11"/>
    <axis xyz="0 0 1"/>
    <limit effort="28.0" velocity="3.141592653589793"/>
    <dynamics damping="0" friction="0"/>
  </joint>
  <link name="ft_frame"/>
  <joint name="wrist_3_link-ft_frame" type="fixed" dont_collapse="true">
    <parent link="wrist_3_link"/>
    <child link="ft_frame"/>
    <origin rpy="3.141592653589793 0 0" xyz="0 0 0"/>
  </joint>
  <!-- ROS-Industrial 'base' frame - base_link to UR 'Base' Coordinates transform -->
  <link name="base"/>
  <joint name="base_link-base_fixed_joint" type="fixed" dont_collapse="true">
    <!-- Note the rotation over Z of pi radians - as base_link is REP-103
           aligned (i.e., has X+ forward, Y+ left and Z+ up), this is needed
           to correctly align 'base' with the 'Base' coordinate system of
           the UR controller.
      -->
    <origin rpy="0 0 3.141592653589793" xyz="0 0 0"/>
    <parent link="base_link"/>
    <child link="base"/>
  </joint>
  <!-- ROS-Industrial 'flange' frame - attachment point for EEF models -->
  <link name="flange"/>
  <joint name="wrist_3-flange" type="fixed" dont_collapse="true">
    <parent link="wrist_3_link"/>
    <child link="flange"/>
    <origin rpy="0 -1.5707963267948966 -1.5707963267948966" xyz="0 0 0"/>
  </joint>
  <!-- ROS-Industrial 'tool0' frame - all-zeros tool frame -->
  <link name="tool0"/>
  <joint name="flange-tool0" type="fixed" dont_collapse="true">
    <!-- default toolframe - X+ left, Y+ up, Z+ front -->
    <origin rpy="1.5707963267948966 0 1.5707963267948966" xyz="0 0 0"/>
    <parent link="flange"/>
    <child link="tool0"/>
  </joint>

  <link name="ur_gripper">
    <visual>
      <geometry>
        <mesh filename="./../meshes/ur5e/ur_gripper.stl" scale="0.001 0.001 0.001"/>
      </geometry>
      <material name="grey"/>
    </visual>
    <collision>
      <geometry>
        <mesh filename="./../meshes/ur5e/ur_gripper.stl" scale="0.001 0.001 0.001"/>
      </geometry>
    </collision>
            <inertial>
            <mass value="0.1" />
            <origin xyz="0 0 0" rpy="0 0 0" />
            <inertia ixx="0.03" iyy="0.03" izz="0.03" ixy="0.0" ixz="0.0" iyz="0.0" />
        </inertial>
  </link>

  
  <joint name="ur_gripper_joint" type="fixed">
    <parent link="wrist_3_link"/>
    <child link="ur_gripper"/>
    <!-- <origin rpy="1.57 -0.7854 -1.57" xyz="-0.002 -0.08423 -0.15968"/> -->
    <origin rpy="1.57 -0.0 -0.785" xyz="0.08423 0.161 -0.0"/><!-- 0.055 0.175 -->
  </joint>


  <link name="ee_link"/>
  <joint name="tool0_ee_link" type="fixed" dont_collapse="true">
    <parent link="tool0"/>
    <child link="ee_link"/>
    <origin rpy="0 0 0" xyz="0 0 0"/>
  </joint>
  
  <material name="camera_aluminum">
    <color rgba="0.5 0.5 0.5 1"/>
  </material>
  <!-- camera body, with origin at bottom screw mount -->
  <link name="camera_link">
    <visual>
      <origin rpy="1.5707963267948966 0 1.5707963267948966" xyz="0.0149 -0.0175 0"/>
      <geometry>
        <!-- <box size="${d435_cam_width} ${d435_cam_height} ${d435_cam_depth}"/> -->
        <mesh filename="./../meshes/realsense/meshes/d435_sim.dae"/>
        <!--<mesh filename="package://realsense2_description/meshes/d435/d435.dae" />-->
      </geometry>
      <material name="camera_aluminum"/>
    </visual>
    <collision>
      <origin rpy="0 0 0" xyz="0 -0.0175 0"/>
      <geometry>
        <box size="0.02505 0.09 0.025"/>
      </geometry>
    </collision>
    <inertial>
      <!-- The following are not reliable values, and should not be used for modeling -->
      <mass value="0.564"/>
      <origin xyz="0 0 0"/>
      <inertia ixx="0.003881243" ixy="0.0" ixz="0.0" iyy="0.000498940" iyz="0.0" izz="0.003879257"/>
    </inertial>
  </link>
  <!-- camera depth joints and links -->
  <joint name="camera_depth_joint" type="fixed" dont_collapse="true">
    <origin rpy="0 0 0" xyz="0 0 0"/>
    <parent link="camera_link"/>
    <child link="camera_depth_frame"/>
  </joint>
  <link name="camera_depth_frame"/>
  <joint name="camera_depth_optical_joint" type="fixed" dont_collapse="true">
    <origin rpy="-1.5707963267948966 0 -1.5707963267948966" xyz="0 0 0"/>
    <parent link="camera_depth_frame"/>
    <child link="camera_depth_optical_frame"/>
  </joint>
  <link name="camera_depth_optical_frame"/>
  <!-- camera left IR joints and links -->
  <joint name="camera_left_ir_joint" type="fixed" dont_collapse="true">
    <origin rpy="0 0 0" xyz="0 0.0 0"/>
    <parent link="camera_depth_frame"/>
    <child link="camera_left_ir_frame"/>
  </joint>
  <link name="camera_left_ir_frame"/>
  <joint name="camera_left_ir_optical_joint" type="fixed" dont_collapse="true">
    <origin rpy="-1.5707963267948966 0 -1.5707963267948966" xyz="0 0 0"/>
    <parent link="camera_left_ir_frame"/>
    <child link="camera_left_ir_optical_frame"/>
  </joint>
  <link name="camera_left_ir_optical_frame"/>
  <!-- camera right IR joints and links -->
  <joint name="camera_right_ir_joint" type="fixed" dont_collapse="true">
    <origin rpy="0 0 0" xyz="0 -0.05 0"/>
    <parent link="camera_depth_frame"/>
    <child link="camera_right_ir_frame"/>
  </joint>
  <link name="camera_right_ir_frame"/>
  <joint name="camera_right_ir_optical_joint" type="fixed" dont_collapse="true">
    <origin rpy="-1.5707963267948966 0 -1.5707963267948966" xyz="0 0 0"/>
    <parent link="camera_right_ir_frame"/>
    <child link="camera_right_ir_optical_frame"/>
  </joint>
  <link name="camera_right_ir_optical_frame"/>
  <!-- camera color joints and links -->
  <joint name="camera_color_joint" type="fixed" dont_collapse="true">
    <origin rpy="0 0 0" xyz="0 0.015 0"/>
    <parent link="camera_depth_frame"/>
    <child link="camera_color_frame"/>
  </joint>
  <link name="camera_color_frame"/>
  <joint name="camera_color_optical_joint" type="fixed" dont_collapse="true">
    <origin rpy="-1.5707963267948966 0 -1.5707963267948966" xyz="0 0 0"/>
    <parent link="camera_color_frame"/>
    <child link="camera_color_optical_frame"/>
  </joint>
  <link name="camera_color_optical_frame"/>

  <joint name="camera_joint" type="fixed" dont_collapse="true">
    <origin rpy="3.1414 0.0 1.5707" xyz="0.055 0.015 0.03"/>
    <!-- <origin rpy="0.0 -0.0 0.0" xyz="-0.0 -0.0 -0.0"/> -->
    <parent link="ur_gripper"/>
    <child link="camera_bottom_screw_frame"/>
  </joint>
  <link name="camera_bottom_screw_frame"/>
  <joint name="camera_link_joint" type="fixed" dont_collapse="true">
    <origin rpy="0 0 0" xyz="0 0.0175 0.0125"/>
    <!-- <origin rpy="0.0 -0.0 0.0" xyz="-0.0 -0.0 -0.0"/> -->
    <parent link="camera_bottom_screw_frame"/>
    <child link="camera_link"/>
  </joint>

  <link name="hand_palm_link">
    <visual>
      <geometry>
        <mesh filename="./../meshes/allegro/meshes/allegro/base_link_left.obj"/>
      </geometry>
      <!-- LEFT -->
      <origin rpy="-1.57 0 0" xyz="0 0 0 "/>
      <!-- RIGHT -->
      <!-- <origin rpy="0 0 0" xyz="0 0 0 "/> -->
      <material name="black">
        <color rgba="0.2 0.2 0.2 1"/>
      </material>
    </visual>
    <collision>
      <origin rpy="0 0 0" xyz="-0.009300 0 -0.0475"/>
      <geometry>
        <!-- <box size="0.0408 0.1130 0.095"/> -->
        <box size="0.01 0.01 0.01"/>
      </geometry>
    </collision>
    <inertial>
      <origin rpy="0 0 0" xyz="0 0 0.0475"/>
      <mass value="0.4154"/>
      <inertia ixx="1e-4" ixy="0.0" ixz="0.0" iyy="1e-4" iyz="0.0" izz="1e-4"/>
    </inertial>
  </link>
  <!-- ============================================================================= -->
  <!-- FINGERS -->
  <!-- RIGHT HAND due to which finger is number 0 -->
  <!-- for LEFT HAND switch the sign of the **offset_origin_y** and **finger_angle_r** parameters-->
  <link name="hand_link_0.0_link">
    <visual>
      <geometry>
        <mesh filename="./../meshes/allegro/meshes/allegro/link_0.0.obj"/>
      </geometry>
      <material name="black"/>
    </visual>
    <collision>
      <geometry>
        <box size="0.0196 0.0275 0.0164"/>
      </geometry>
      <origin rpy="0 0 0" xyz="0 0 0.0082"/>
    </collision>
    <inertial>
      <mass value="0.0119"/>
      <origin rpy="0 0 0" xyz="0 0 0"/>
      <inertia ixx="1.01666658333e-06" ixy="0.0" ixz="0.0" iyy="6.47677333333e-07" iyz="0.0" izz="1.01666658333e-06"/>
    </inertial>
  </link>
  <joint name="joint_0.0" type="revolute">
    <axis xyz="0 0 1"/>
    <limit effort="0.35" lower="-0.47" upper="0.47" velocity="6.283"/>
    <parent link="hand_palm_link"/>
    <child link="hand_link_0.0_link"/>
    <origin rpy="0.08726646255 0 0" xyz="0 -0.0435 -0.001542"/>
  </joint>
  <link name="hand_link_1.0_link">
    <visual>
      <geometry>
        <mesh filename="./../meshes/allegro/meshes/allegro/link_1.0.obj"/>
      </geometry>
      <material name="black"/>
    </visual>
    <collision>
      <geometry>
        <box size="0.0196 0.0275 0.054"/>
      </geometry>
      <origin rpy="0 0 0" xyz="0 0 0.027"/>
    </collision>
    <inertial>
      <mass value="0.065"/>
      <origin rpy="0 0 0" xyz="0 0 0"/>
      <inertia ixx="7.95654166667e-05" ixy="1.7199e-05" ixz="8.75875e-06" iyy="2.47088833333e-05" iyz="2.413125e-05" izz="7.95654166667e-05"/>
    </inertial>
  </link>
  <joint name="joint_1.0" type="revolute">
    <limit effort="0.35" lower="-0.196" upper="1.61" velocity="6.283"/>
    <axis xyz="0 1 0"/>
    <parent link="hand_link_0.0_link"/>
    <child link="hand_link_1.0_link"/>
    <origin xyz="0 0 0.0164"/>
  </joint>

  <link name="finger_1_contact_1">
    <visual>
      <geometry>
        <box size="0.00125 0.017 0.065"/>
      </geometry>
      <material name="blue">
        <color rgba="0 0 1 1"/>
      </material>
    </visual>
    <collision>
      <geometry>
        <box size="0.00125 0.017 0.065"/>
      </geometry>
    </collision>
  </link>

  <joint name="finger_1_contact2_1" type="fixed" dont_collapse="true">
    <parent link="hand_link_1.0_link"/>
    <child link="finger_1_contact_1"/>
    <origin rpy="0 0 0" xyz="0.01 0 0.0275"/>
  </joint>

  <link name="hand_link_2.0_link">
    <visual>
      <geometry>
        <mesh filename="./../meshes/allegro/meshes/allegro/link_2.0.obj"/>
      </geometry>
      <material name="black"/>
    </visual>
    <collision>
      <geometry>
        <box size="0.0196 0.0275 0.0384"/>
      </geometry>
      <origin rpy="0 0 0" xyz="0 0 0.0192"/>
    </collision>
    <inertial>
      <mass value="0.0355"/>
      <origin rpy="0 0 0" xyz="0 0 0"/>
      <inertia ixx="2.63979183333e-05" ixy="6.67968e-06" ixz="4.783625e-06" iyy="1.34948516667e-05" iyz="9.372e-06" izz="2.63979183333e-05"/>
    </inertial>
  </link>
  <joint name="joint_2.0" type="revolute">
    <axis xyz="0 1 0"/>
    <limit effort="0.35" lower="-0.174" upper="1.709" velocity="6.283"/>
    <parent link="hand_link_1.0_link"/>
    <child link="hand_link_2.0_link"/>
    <origin xyz="0 0 0.054"/>
  </joint>

  <link name="finger_1_contact_2">
    <visual>
      <geometry>
        <box size="0.00125 0.017 0.0375"/>
      </geometry>
      <material name="blue">
        <color rgba="0 0 1 1"/>
      </material>
    </visual>
    <collision>
      <geometry>
        <box size="0.00125 0.017 0.0375"/>
      </geometry>
    </collision>
  </link>

  <joint name="finger_1_contact2_2" type="fixed" dont_collapse="true">
    <parent link="hand_link_2.0_link"/>
    <child link="finger_1_contact_2"/>
    <origin rpy="0 0 0" xyz="0.01 0 0.0325"/>
  </joint>

  <link name="hand_link_3.0_link">
    <visual>
      <geometry>
        <mesh filename="./../meshes/allegro/meshes/allegro/link_3.0.obj"/>
      </geometry>
      <material name="black"/>
    </visual>
    <collision>
      <geometry>
        <sphere radius="0.0001"/>
      </geometry>
      <origin rpy="0 0 0" xyz="0 0 0.01335"/>
    </collision>
    <inertial>
      <mass value="0.0096"/>
      <origin rpy="0 0 0" xyz="0 0 0"/>
      <inertia ixx="4.701248e-06" ixy="1.255968e-06" ixz="1.2936e-06" iyy="3.649312e-06" iyz="1.7622e-06" izz="4.701248e-06"/>
    </inertial>
  </link>
  <joint name="joint_3.0" type="revolute">
    <axis xyz="0 1 0"/>
    <limit effort="0.35" lower="-0.227" upper="1.618" velocity="6.283"/>
    <parent link="hand_link_2.0_link"/>
    <child link="hand_link_3.0_link"/>
    <origin xyz="0 0 0.0384"/>
  </joint>

  <!-- <link name="finger_1_contact_3">
    <visual>
      <geometry>
        <box size="0.00125 0.022 0.0375"/>
      </geometry>
      <material name="blue">
        <color rgba="0 0 1 1"/>
      </material>
    </visual>
    <collision>
      <geometry>
        <box size="0.00125 0.022 0.0375"/>
      </geometry>
    </collision>
  </link>

  <joint name="finger_1_contact2_3" type="fixed" dont_collapse="true">
    <parent link="hand_link_3.0_link"/>
    <child link="finger_1_contact_3"/>
    <origin rpy="0 0 0" xyz="0.01 0 -0.005"/>
  </joint> -->

  <link name="hand_link_3.0_link_tip_link">
    <visual>
      <geometry>
        <mesh filename="./../meshes/allegro/meshes/allegro/digit.obj"/>
      </geometry>
      <origin rpy="0 0 0" xyz="-0.02 0.000 -0.015"/>
      <material name="white">
        <color rgba=".9 .9 .9 1"/>
      </material>
    </visual>
    <collision>
      <geometry>
        <sphere radius="0.01235"/>
      </geometry>
      <origin rpy="0 0 0" xyz="0.000 0.000 0"/>
    </collision>
    <inertial>
      <mass value="0.0168"/>
      <origin rpy="0 0 0" xyz="0 0 0"/>
      <inertia ixx="9.68e-07" ixy="0" ixz="0" iyy="9.68e-07" iyz="0" izz="9.68e-07"/>
    </inertial>
  </link>
  <joint name="joint_3.0_tip_link" type="fixed" dont_collapse="true">
    <parent link="hand_link_3.0_link"/>
    <child link="hand_link_3.0_link_tip_link"/>
    <origin rpy="0 0 0" xyz="0.02 0 0.03"/>
  </joint>

  <link name="finger_1_contact_3_tip">
    <visual>
      <geometry>
        <box size="0.00075 0.02 0.02"/>
      </geometry>
      <material name="blue">
        <color rgba="0 0 1 1"/>
      </material>
    </visual>
    <collision>
      <geometry>
        <box size="0.00075 0.02 0.02"/>
      </geometry>
    </collision>
  </link>

  <joint name="finger_1_contact2_3_tip" type="fixed" dont_collapse="true">
    <parent link="hand_link_3.0_link_tip_link"/>
    <child link="finger_1_contact_3_tip"/>
    <origin rpy="0 0 0" xyz="0 0 0"/>
  </joint>

  <link name="hand_link_4.0_link">
    <visual>
      <geometry>
        <mesh filename="./../meshes/allegro/meshes/allegro/link_0.0.obj"/>
      </geometry>
      <material name="black"/>
    </visual>
    <collision>
      <geometry>
        <box size="0.0196 0.0275 0.0164"/>
      </geometry>
      <origin rpy="0 0 0" xyz="0 0 0.0082"/>
    </collision>
    <inertial>
      <mass value="0.0119"/>
      <origin rpy="0 0 0" xyz="0 0 0"/>
      <inertia ixx="1.01666658333e-06" ixy="0.0" ixz="0.0" iyy="6.47677333333e-07" iyz="0.0" izz="1.01666658333e-06"/>
    </inertial>
  </link>
  <joint name="joint_4.0" type="revolute">
    <axis xyz="0 0 1"/>
    <limit effort="0.35" lower="-0.47" upper="0.47" velocity="6.283"/>
    <parent link="hand_palm_link"/>
    <child link="hand_link_4.0_link"/>
    <origin rpy="0.0 0 0" xyz="0 0 0.0007"/>
  </joint>
  <link name="hand_link_5.0_link">
    <visual>
      <geometry>
        <mesh filename="./../meshes/allegro/meshes/allegro/link_1.0.obj"/>
      </geometry>
      <material name="black"/>
    </visual>
    <collision>
      <geometry>
        <box size="0.0196 0.0275 0.054"/>
      </geometry>
      <origin rpy="0 0 0" xyz="0 0 0.027"/>
    </collision>
    <inertial>
      <mass value="0.065"/>
      <origin rpy="0 0 0" xyz="0 0 0"/>
      <inertia ixx="7.95654166667e-05" ixy="1.7199e-05" ixz="8.75875e-06" iyy="2.47088833333e-05" iyz="2.413125e-05" izz="7.95654166667e-05"/>
    </inertial>
  </link>
  <joint name="joint_5.0" type="revolute">
    <limit effort="0.35" lower="-0.196" upper="1.61" velocity="6.283"/>
    <axis xyz="0 1 0"/>
    <parent link="hand_link_4.0_link"/>
    <child link="hand_link_5.0_link"/>
    <origin xyz="0 0 0.0164"/>
  </joint>

  <link name="finger_2_contact_5">
    <visual>
      <geometry>
        <box size="0.00125 0.017 0.065"/>
      </geometry>
      <material name="blue">
        <color rgba="0 0 1 1"/>
      </material>
    </visual>
    <collision>
      <geometry>
        <box size="0.00125 0.017 0.065"/>
      </geometry>
    </collision>
  </link>

  <joint name="finger_2_contact5_1" type="fixed" dont_collapse="true">
    <parent link="hand_link_5.0_link"/>
    <child link="finger_2_contact_5"/>
    <origin rpy="0 0 0" xyz="0.01 0 0.0275"/>
  </joint>

  <link name="hand_link_6.0_link">
    <visual>
      <geometry>
        <mesh filename="./../meshes/allegro/meshes/allegro/link_2.0.obj"/>
      </geometry>
      <material name="black"/>
    </visual>
    <collision>
      <geometry>
        <box size="0.0196 0.0275 0.0384"/>
      </geometry>
      <origin rpy="0 0 0" xyz="0 0 0.0192"/>
    </collision>
    <inertial>
      <mass value="0.0355"/>
      <origin rpy="0 0 0" xyz="0 0 0"/>
      <inertia ixx="2.63979183333e-05" ixy="6.67968e-06" ixz="4.783625e-06" iyy="1.34948516667e-05" iyz="9.372e-06" izz="2.63979183333e-05"/>
    </inertial>
  </link>
  <joint name="joint_6.0" type="revolute">
    <axis xyz="0 1 0"/>
    <limit effort="0.35" lower="-0.174" upper="1.709" velocity="6.283"/>
    <parent link="hand_link_5.0_link"/>
    <child link="hand_link_6.0_link"/>
    <origin xyz="0 0 0.054"/>
  </joint>

  <link name="finger_2_contact_6">
    <visual>
      <geometry>
        <box size="0.00125 0.017 0.0375"/>
      </geometry>
      <material name="blue">
        <color rgba="0 0 1 1"/>
      </material>
    </visual>
    <collision>
      <geometry>
        <box size="0.00125 0.017 0.0375"/>
      </geometry>
    </collision>
  </link>

  <joint name="finger_2_contact6_2" type="fixed" dont_collapse="true">
    <parent link="hand_link_6.0_link"/>
    <child link="finger_2_contact_6"/>
    <origin rpy="0 0 0" xyz="0.01 0 0.0325"/>
  </joint>

  <link name="hand_link_7.0_link">
    <visual>
      <geometry>
        <mesh filename="./../meshes/allegro/meshes/allegro/link_3.0.obj"/>
      </geometry>
      <material name="black"/>
    </visual>
    <collision>
      <geometry>
        <sphere radius="0.0001"/>
      </geometry>
    </collision>
    <inertial>
      <mass value="0.0096"/>
      <origin rpy="0 0 0" xyz="0 0 0"/>
      <inertia ixx="4.701248e-06" ixy="1.255968e-06" ixz="1.2936e-06" iyy="3.649312e-06" iyz="1.7622e-06" izz="4.701248e-06"/>
    </inertial>
  </link>
  <joint name="joint_7.0" type="revolute">
    <axis xyz="0 1 0"/>
    <limit effort="0.35" lower="-0.227" upper="1.618" velocity="6.283"/>
    <parent link="hand_link_6.0_link"/>
    <child link="hand_link_7.0_link"/>
    <origin xyz="0 0 0.0384"/>
  </joint>

  <!-- <link name="finger_2_contact_7">
    <visual>
      <geometry>
        <box size="0.00125 0.022 0.0375"/>
      </geometry>
      <material name="blue">
        <color rgba="0 0 1 1"/>
      </material>
    </visual>
    <collision>
      <geometry>
        <box size="0.00125 0.022 0.0375"/>
      </geometry>
    </collision>
  </link>

  <joint name="finger_2_contact2_7" type="fixed" dont_collapse="true">
    <parent link="hand_link_7.0_link"/>
    <child link="finger_2_contact_7"/>
    <origin rpy="0 0 0" xyz="0.01 0 -0.005"/>
  </joint> -->

  <link name="hand_link_7.0_link_tip_link">
    <visual>
      <geometry>
        <mesh filename="./../meshes/allegro/meshes/allegro/digit.obj"/>
      </geometry>
      <origin rpy="0 0 0" xyz="-0.02 0.000 -0.015"/>
      <material name="white">
        <color rgba=".9 .9 .9 1"/>
      </material>
    </visual>
    <collision>
      <geometry>
        <sphere radius="0.01235"/>
      </geometry>
    </collision>
    <inertial>
      <mass value="0.0168"/>
      <origin rpy="0 0 0" xyz="0 0 0"/>
      <inertia ixx="9.68e-07" ixy="0" ixz="0" iyy="9.68e-07" iyz="0" izz="9.68e-07"/>
    </inertial>
  </link>
  <joint name="joint_7.0_tip_link" type="fixed" dont_collapse="true">
    <parent link="hand_link_7.0_link"/>
    <child link="hand_link_7.0_link_tip_link"/>
    <origin rpy="0 0 0" xyz="0.02 0 0.03"/>
  </joint>

  <link name="finger_2_contact_7_tip">
    <visual>
      <geometry>
        <box size="0.00075 0.02 0.02"/>
      </geometry>
      <material name="blue">
        <color rgba="0 0 1 1"/>
      </material>
    </visual>
    <collision>
      <geometry>
        <box size="0.00075 0.02 0.02"/>
      </geometry>
    </collision>
  </link>

  <joint name="finger_2_contact2_7_tip" type="fixed" dont_collapse="true">
    <parent link="hand_link_7.0_link_tip_link"/>
    <child link="finger_2_contact_7_tip"/>
    <origin rpy="0 0 0" xyz="0 0 0"/>
  </joint>

  <link name="hand_link_8.0_link">
    <visual>
      <geometry>
        <mesh filename="./../meshes/allegro/meshes/allegro/link_0.0.obj"/>
      </geometry>
      <material name="black"/>
    </visual>
    <collision>
      <geometry>
        <box size="0.0196 0.0275 0.0164"/>
      </geometry>
      <origin rpy="0 0 0" xyz="0 0 0.0082"/>
    </collision>
    <inertial>
      <mass value="0.0119"/>
      <origin rpy="0 0 0" xyz="0 0 0"/>
      <inertia ixx="1.01666658333e-06" ixy="0.0" ixz="0.0" iyy="6.47677333333e-07" iyz="0.0" izz="1.01666658333e-06"/>
    </inertial>
  </link>
  <joint name="joint_8.0" type="revolute">
    <axis xyz="0 0 1"/>
    <limit effort="0.35" lower="-0.47" upper="0.47" velocity="6.283"/>
    <parent link="hand_palm_link"/>
    <child link="hand_link_8.0_link"/>
    <origin rpy="-0.08726646255 0 0" xyz="0 0.0435 -0.001542"/>
  </joint>
  <link name="hand_link_9.0_link">
    <visual>
      <geometry>
        <mesh filename="./../meshes/allegro/meshes/allegro/link_1.0.obj"/>
      </geometry>
      <material name="black"/>
    </visual>
    <collision>
      <geometry>
        <box size="0.0196 0.0275 0.054"/>
      </geometry>
      <origin rpy="0 0 0" xyz="0 0 0.027"/>
    </collision>
    <inertial>
      <mass value="0.065"/>
      <origin rpy="0 0 0" xyz="0 0 0"/>
      <inertia ixx="7.95654166667e-05" ixy="1.7199e-05" ixz="8.75875e-06" iyy="2.47088833333e-05" iyz="2.413125e-05" izz="7.95654166667e-05"/>
    </inertial>
  </link>
  <joint name="joint_9.0" type="revolute">
    <limit effort="0.35" lower="-0.196" upper="1.61" velocity="6.283"/>
    <axis xyz="0 1 0"/>
    <parent link="hand_link_8.0_link"/>
    <child link="hand_link_9.0_link"/>
    <origin xyz="0 0 0.0164"/>
  </joint>

  <link name="finger_3_contact_9">
    <visual>
      <geometry>
        <box size="0.00125 0.017 0.065"/>
      </geometry>
      <material name="blue">
        <color rgba="0 0 1 1"/>
      </material>
    </visual>
    <collision>
      <geometry>
        <box size="0.00125 0.017 0.065"/>
      </geometry>
    </collision>
  </link>

  <joint name="finger_3_contact9_1" type="fixed" dont_collapse="true">
    <parent link="hand_link_9.0_link"/>
    <child link="finger_3_contact_9"/>
    <origin rpy="0 0 0" xyz="0.01 0 0.0275"/>
  </joint>

  <link name="hand_link_10._link">
    <visual>
      <geometry>
        <mesh filename="./../meshes/allegro/meshes/allegro/link_2.0.obj"/>
      </geometry>
      <material name="black"/>
    </visual>
    <collision>
      <geometry>
        <box size="0.0196 0.0275 0.0384"/>
      </geometry>
      <origin rpy="0 0 0" xyz="0 0 0.0192"/>
    </collision>
    <inertial>
      <mass value="0.0355"/>
      <origin rpy="0 0 0" xyz="0 0 0"/>
      <inertia ixx="2.63979183333e-05" ixy="6.67968e-06" ixz="4.783625e-06" iyy="1.34948516667e-05" iyz="9.372e-06" izz="2.63979183333e-05"/>
    </inertial>
  </link>
  <joint name="joint_10.0" type="revolute">
    <axis xyz="0 1 0"/>
    <limit effort="0.35" lower="-0.174" upper="1.709" velocity="6.283"/>
    <parent link="hand_link_9.0_link"/>
    <child link="hand_link_10._link"/>
    <origin xyz="0 0 0.054"/>
  </joint>

  <link name="finger_3_contact_10">
    <visual>
      <geometry>
        <box size="0.00125 0.017 0.0375"/>
      </geometry>
      <material name="blue">
        <color rgba="0 0 1 1"/>
      </material>
    </visual>
    <collision>
      <geometry>
        <box size="0.00125 0.017 0.0375"/>
      </geometry>
    </collision>
  </link>

  <joint name="finger_3_contact10_2" type="fixed" dont_collapse="true">
    <parent link="hand_link_10._link"/>
    <child link="finger_3_contact_10"/>
    <origin rpy="0 0 0" xyz="0.01 0 0.0325"/>
  </joint>

  <link name="hand_link_11._link">
    <visual>
      <geometry>
        <mesh filename="./../meshes/allegro/meshes/allegro/link_3.0.obj"/>
      </geometry>
      <material name="black"/>
    </visual>
    <collision>
      <geometry>
        <sphere radius="0.0001"/>
      </geometry>
    </collision>
    <inertial>
      <mass value="0.0096"/>
      <origin rpy="0 0 0" xyz="0 0 0"/>
      <inertia ixx="4.701248e-06" ixy="1.255968e-06" ixz="1.2936e-06" iyy="3.649312e-06" iyz="1.7622e-06" izz="4.701248e-06"/>
    </inertial>
  </link>
  <joint name="joint_11.0" type="revolute">
    <axis xyz="0 1 0"/>
    <limit effort="0.35" lower="-0.227" upper="1.618" velocity="6.283"/>
    <parent link="hand_link_10._link"/>
    <child link="hand_link_11._link"/>
    <origin xyz="0 0 0.0384"/>
  </joint>

  <!-- <link name="finger_3_contact_11">
    <visual>
      <geometry>
        <box size="0.00125 0.022 0.0375"/>
      </geometry>
      <material name="blue">
        <color rgba="0 0 1 1"/>
      </material>
    </visual>
    <collision>
      <geometry>
        <box size="0.00125 0.022 0.0375"/>
      </geometry>
    </collision>
  </link>

  <joint name="finger_3_contact2_11" type="fixed" dont_collapse="true">
    <parent link="hand_link_11._link"/>
    <child link="finger_3_contact_11"/>
    <origin rpy="0 0 0" xyz="0.01 0 -0.005"/>
  </joint> -->

  <link name="hand_link_11._link_tip_link">
    <visual>
      <geometry>
        <mesh filename="./../meshes/allegro/meshes/allegro/digit.obj"/>
      </geometry>
      <origin rpy="0 0 0" xyz="-0.02 0.000 -0.015"/>
      <material name="white">
        <color rgba=".9 .9 .9 1"/>
      </material>
    </visual>
    <collision>
      <geometry>
        <sphere radius="0.01235"/>
      </geometry>
    </collision>
    <inertial>
      <mass value="0.0168"/>
      <origin rpy="0 0 0" xyz="0 0 0"/>
      <inertia ixx="9.68e-07" ixy="0" ixz="0" iyy="9.68e-07" iyz="0" izz="9.68e-07"/>
    </inertial>
  </link>
  <joint name="joint_11.0_tip_link" type="fixed" dont_collapse="true">
    <parent link="hand_link_11._link"/>
    <child link="hand_link_11._link_tip_link"/>
    <origin rpy="0 0 0" xyz="0.02 0 0.03"/>
  </joint>

  <link name="finger_3_contact_11_tip">
    <visual>
      <geometry>
        <box size="0.00075 0.02 0.02"/>
      </geometry>
      <material name="blue">
        <color rgba="0 0 1 1"/>
      </material>
    </visual>
    <collision>
      <geometry>
        <box size="0.00075 0.02 0.02"/>
      </geometry>
    </collision>
  </link>

  <joint name="finger_3_contact2_11_tip" type="fixed" dont_collapse="true">
    <parent link="hand_link_11._link_tip_link"/>
    <child link="finger_3_contact_11_tip"/>
    <origin rpy="0 0 0" xyz="0 0 0"/>
  </joint>

  <!-- THUMB -->
  <link name="hand_link_12._link">
    <visual>
      <geometry>
        <!-- RIGHT -->
        <!-- <mesh filename="./../meshes/allegro/meshes/allegro/link_12.0_right.obj"/> -->
        <!-- LEFT -->
        <mesh filename="./../meshes/allegro/meshes/allegro/link_12.0_left.obj" />
      </geometry>
      <material name="black">
        <color rgba=".2 .2 .2 1"/>
      </material>
    </visual>
    <collision>
      <geometry>
        <box size="0.0358 0.034 0.0455"/>
      </geometry>
      <!-- RIGHT -->
      <!-- <origin rpy="0 0 0" xyz="-0.0179 0.009 0.0145"/> -->
      <!-- LEFT -->
      <origin rpy="0 0 0" xyz="-0.0179 -0.09 0.145"/>
    </collision>
    <inertial>
      <mass value="0.0176"/>
      <origin rpy="0 0 0" xyz="0 0 0"/>
      <inertia ixx="1.89273333333e-5" ixy="7.16716e-06" ixz="5.35568e-06" iyy="1.43008213333e-05" iyz="6.8068e-06" izz="1.89273333333e-05"/>
    </inertial>
  </link>
  <joint name="joint_12.0" type="revolute">
    <axis xyz="1 0 0"/>
    <limit effort="0.35" lower="0.263" upper="1.396" velocity="6.283"/>
    <parent link="hand_palm_link"/>
    <child link="hand_link_12._link"/>
    <origin rpy="0 -1.65806278845 1.5707963259" xyz="-0.0182 -0.019333 -0.045987"/>
  </joint>
  <link name="hand_link_13._link">
    <visual>
      <geometry>
        <mesh filename="./../meshes/allegro/meshes/allegro/link_13.0.obj"/>
      </geometry>
      <material name="black">
        <color rgba=".2 .2 .2 1"/>
      </material>
    </visual>
    <collision>
      <geometry>
        <box size="0.0196 0.0275 0.0177"/>
      </geometry>
      <origin rpy="0 0 0" xyz="0 0 0.00885"/>
    </collision>
    <inertial>
      <mass value="0.0119"/>
      <origin rpy="0 0 0" xyz="0 0 0"/>
      <inertia ixx="4.24250866667e-06" ixy="1.032087e-06" ixz="1.603525e-06" iyy="4.52362633333e-06" iyz="1.44808125e-06" izz="4.24250866667e-06"/>
    </inertial>
  </link>
  <joint name="joint_13.0" type="revolute">
    <axis xyz="0 0 -1"/>
    <limit effort="0.35" lower="-0.105" upper="1.163" velocity="6.283"/>
    <parent link="hand_link_12._link"/>
    <child link="hand_link_13._link"/>
    <!-- LEFT -->
    <origin xyz="-0.027 -0.005 0" rpy="0 0 -1.57"/> <!-- -0.027 -0.005 -0.0399 -->
    <!-- RIGHT -->
    <!-- <origin xyz="-0.027 0.005 0.0399"/> -->
  </joint>
  <link name="hand_link_14._link">
    <visual>
      <geometry>
        <mesh filename="./../meshes/allegro/meshes/allegro/link_14.0.obj"/>
      </geometry>
      <material name="black">
      </material>
    </visual>
    <collision>
      <geometry>
        <box size="0.0196 0.0275 0.0514"/>
      </geometry>
      <origin rpy="0 0 0" xyz="0 0 0.0257"/>
    </collision>
    <inertial>
      <mass value="0.038"/>
      <origin rpy="0 0 0" xyz="0 0 0"/>
      <inertia ixx="4.30439933333e-05" ixy="9.57068e-06" ixz="5.1205e-06" iyy="1.44451933333e-05" iyz="1.342825e-05" izz="4.30439933333e-05"/>
    </inertial>
  </link>
  <joint name="joint_14.0" type="revolute">
    <axis xyz="0 1 0"/>
    <limit effort="0.35" lower="-0.189" upper="1.644" velocity="6.283"/>
    <parent link="hand_link_13._link"/>
    <child link="hand_link_14._link"/>
    <origin xyz="0 0 0.0177"/>
  </joint>

<link name="finger_4_contact_14">
    <visual>
      <geometry>
        <box size="0.00125 0.022 0.0375"/>
      </geometry>
      <material name="blue">
        <color rgba="0 0 1 1"/>
      </material>
    </visual>
    <collision>
      <geometry>
        <box size="0.00125 0.022 0.0375"/>
      </geometry>
    </collision>
  </link>

  <joint name="finger_4_contact2_14" type="fixed" dont_collapse="true">
    <parent link="hand_link_14._link"/>
    <child link="finger_4_contact_14"/>
    <origin rpy="0 0 0" xyz="0.01 0 0.005"/>
  </joint>

  <link name="hand_link_15._link">
    <visual>
      <geometry>
        <mesh filename="./../meshes/allegro/meshes/allegro/link_15.0.obj"/>
      </geometry>
      <material name="black">
    	</material>
    </visual>
    <collision>
      <geometry>
        <sphere radius="0.0001"/>
      </geometry>
      <origin rpy="0 0 0" xyz="0 0 0.02115"/>
    </collision>
    <inertial>
      <mass value="0.0388"/>
      <origin rpy="0 0 0" xyz="0 0 0"/>
      <inertia ixx="3.29223173333e-05" ixy="8.042076e-06" ixz="5.2283e-06" iyy="1.47493026667e-5" iyz="1.1283525e-5" izz="3.29223173333e-05"/>
    </inertial>
  </link>
  <joint name="joint_15.0" type="revolute">
    <axis xyz="0 1 0"/>
    <limit effort="0.35" lower="-0.162" upper="1.719" velocity="6.283"/>
    <parent link="hand_link_14._link"/>
    <child link="hand_link_15._link"/>
    <origin xyz="0 0 0.0514"/>
  </joint>

  <link name="finger_4_contact_15">
    <visual>
      <geometry>
        <box size="0.00125 0.022 0.035"/>
      </geometry>
      <material name="blue">
        <color rgba="0 0 1 1"/>
      </material>
    </visual>
    <collision>
      <geometry>
        <box size="0.00125 0.022 0.035"/>
      </geometry>
    </collision>
  </link>

  <joint name="finger_4_contact2_15" type="fixed" dont_collapse="true">
    <parent link="hand_link_15._link"/>
    <child link="finger_4_contact_15"/>
    <origin rpy="0 0 0" xyz="0.01 0 0.005"/>
  </joint>

  <link name="hand_link_15._link_tip_link">
    <visual>
      <geometry>
        <mesh filename="./../meshes/allegro/meshes/allegro/digit.obj"/>
      </geometry>
      <origin rpy="0 0 0" xyz="-0.02 0.000 -0.015"/>
      <material name="white">
        <color rgba=".9 .9 .9 1"/>
      </material>
    </visual>
    <collision>
      <geometry>
        <sphere radius="0.01235"/>
      </geometry>
    </collision>
    <inertial>
      <mass value="0.0168"/>
      <origin rpy="0 0 0" xyz="0 0 0"/>
      <inertia ixx="9.68e-07" ixy="0" ixz="0" iyy="9.68e-07" iyz="0" izz="9.68e-07"/>
    </inertial>
  </link>
  <joint name="joint_15.0_tip_link" type="fixed" dont_collapse="true">
    <parent link="hand_link_15._link"/>
    <child link="hand_link_15._link_tip_link"/>
    <origin rpy="0 0 0" xyz="0.02 0 0.0455"/>
  </joint>

  <link name="finger_4_contact_15_tip">
    <visual>
      <geometry>
        <box size="0.00075 0.02 0.02"/>
      </geometry>
      <material name="blue">
        <color rgba="0 0 1 1"/>
      </material>
    </visual>
    <collision>
      <geometry>
        <box size="0.00075 0.02 0.02"/>
      </geometry>
    </collision>
  </link>

  <joint name="finger_4_contact2_15_tip" type="fixed" dont_collapse="true">
    <parent link="hand_link_15._link_tip_link"/>
    <child link="finger_4_contact_15_tip"/>
    <origin rpy="0 0 0" xyz="0.0 0 0.0"/>
  </joint>


  <joint name="palm_2_ur" type="fixed" dont_collapse="true">
    <parent link="ee_link"/>
    <child link="hand_palm_link"/>
    <origin rpy="0 0 5.5" xyz="0.0 0 0.1175"/>
  </joint>
  
</robot>
